Workbook

Sheet Read me
A1: CardioAI: data import list for Mayo Clinic Platform
A3: Purpose | B3: Every data element, code and table the five CardioAI risk calculators (AMI, Stroke, Heart Failure, Sudden Cardiac Death, Atrial Fibrillation) import from Mayo Clinic Platform for training, plus the Python packages the workspace needs.
A4: Prepared by | B4: CardioAI (cardioailive.com)
A5: Date | B5: 2026-10-21
A6: Source of truth | B6: Generated from the CardioAI code sets (cardioai_core/schema.py, training/codesets.py, training/code_lists/candidate_codes.csv). The extraction SQL uses exactly these lists.
A7: Data model | B7: OMOP CDM on Spark SQL, plus Mayo native tables FACT_ECHO_TEST and FACT_RADIOLOGY.
A8: Population | B8: Adults aged 18–89 at the index visit. No pediatric patients. Full criteria on the Eligibility tab.
A9: Index date | B9: One outpatient visit per patient, 2012-01-01 to 2019-12-31.
A10: Time windows | B10: Baseline labs, vitals and reports: 730 days up to index. Medications: 365 days before index. History: any time on or before index. Outcomes: any time after index. Adjudication evidence: around each candidate event (see each tab).
A11: Data leaving the workspace | B11: None at patient level. Only the export-reviewed model bundle and aggregate metrics (cells < 11 suppressed).
A12: Codes in this workbook
A13: Labs & vitals (LOINC) | B13: =COUNTA('Labs & vitals'!E5:E1000) -> 38
A14: History diagnoses (ICD) | B14: =COUNTA('History diagnoses'!E5:E5000) -> 752
A15: Outcome diagnoses (ICD) | B15: =COUNTA('Outcome diagnoses'!C5:C5000) -> 334
A16: Procedure code groups | B16: =COUNTA(Procedures!D5:D1000) -> 22
A17: Medication classes (ATC) | B17: =COUNTA(Medications!D5:D1000) -> 14
A19: Tabs
A20: By calculator | B20: What each calculator imports, and code counts per calculator
A21: Source tables | B21: OMOP and native tables and the columns read
A22: Labs & vitals | B22: LOINC codes: model inputs, eligibility, adjudication evidence
A23: History diagnoses | B23: Every ICD-10-CM / ICD-9-CM code behind each history flag
A24: Outcome diagnoses | B24: Every ICD code that creates a candidate outcome event (included = yes), and the excluded ones
A25: Procedures | B25: CPT4 and ICD-10-PCS codes used as adjudication evidence
A26: Medications | B26: ATC classes (mapped to RxNorm in the workspace)
A27: Notes & reports | B27: Clinical notes, radiology and echo reports, and their windows
A28: Concepts & demographics | B28: Person, visit, death and status concepts
A29: Eligibility | B29: Inclusion and exclusion criteria, with age bounds
A30: Python packages | B30: Packages the code imports, versions, and whether the workspace needs them
A31: Open confirmations | B31: Questions for MCP. Yellow cells are for MCP's answers
A33: Notes | B33: ICD-10-CM codes: CMS/CDC release of 1 April 2026; ICD-9-CM: CMS v32 (final). 'header' codes are not billable today but appear in older records. CPT descriptions are not reproduced (AMA licence); MCP's concept table has them. LOINC names are short forms; verify assay codes against Mayo's lab catalogue.

Sheet By calculator
A1: What each calculator imports
A2: Y = the calculator uses this element. All five models share the same baseline inputs; they differ in outcome codes and adjudication evidence. Code counts below are formulas over the code tabs.
A4: Data element group | B4: Includes | C4: AMI | D4: Stroke | E4: HF | F4: SCD | G4: AF
A5: Demographics | B5: age, sex, race/ethnicity, height, weight, BMI | C5: Y | D5: Y | E5: Y | F5: Y | G5: Y
A6: History flags | B6: prior MI, prior stroke/TIA, angina, heart failure, AF, family history CAD, hypertension, PAD, smoking, diabetes | C6: Y | D6: Y | E6: Y | F6: Y | G6: Y
A7: Vitals and labs | B7: SBP, DBP, total/HDL/LDL cholesterol, triglycerides, glucose, HbA1c, hs-CRP, eGFR | C7: Y | D7: Y | E7: Y | F7: Y | G7: Y
A8: Imaging values | B8: Coronary calcium (radiology reports), LVEF (echo) | C8: Y | D8: Y | E8: Y | F8: Y | G8: Y
A9: Medications | B9: statin, aspirin, ACE-I/ARB, beta blocker, anticoagulant, any antihypertensive | C9: Y | D9: Y | E9: Y | F9: Y | G9: Y
A10: Outcome diagnosis codes | B10: Candidate events after index (one family per calculator) | C10: Y | D10: Y | E10: Y | F10: Y | G10: Y
A11: Troponin I / T, hs-troponin | B11: AMI adjudication evidence | C11: Y
A12: BNP / NT-proBNP | B12: HF adjudication evidence | E12: Y
A13: Coronary angiography, PCI | B13: AMI adjudication evidence | C13: Y
A14: Head CT/MRI, thrombolysis, thrombectomy | B14: Stroke adjudication evidence | D14: Y
A15: Echocardiogram, event-window echo reports | B15: HF adjudication evidence (HFrEF / HFpEF) | E15: Y
A16: CPR, defibrillation, ICD implant, death date | B16: SCD adjudication evidence | F16: Y
A17: Cardioversion, cardiac surgery | B17: AF adjudication evidence; post-operative AF rule | G17: Y
A18: Event-window clinical notes | B18: Adjudication evidence for every calculator | C18: Y | D18: Y | E18: Y | F18: Y | G18: Y
A19: Visit setting, primary diagnosis | B19: Adjudication evidence | C19: Y | D19: Y | E19: Y | F19: Y
A21: Codes per calculator
A22: Count | C22: AMI | D22: Stroke | E22: HF | F22: SCD | G22: AF
A23: Outcome ICD codes (included) | C23: =COUNTIFS('Outcome diagnoses'!$A$5:$A$5000,"AMI",'Outcome diagnoses'!$G$5:$G$5000,"yes") -> 44 | D23: =COUNTIFS('Outcome diagnoses'!$A$5:$A$5000,"Stroke",'Outcome diagnoses'!$G$5:$G$5000,"yes") -> 177 | E23: =COUNTIFS('Outcome diagnoses'!$A$5:$A$5000,"HF",'Outcome diagnoses'!$G$5:$G$5000,"yes") -> 61 | F23: =COUNTIFS('Outcome diagnoses'!$A$5:$A$5000,"SCD",'Outcome diagnoses'!$G$5:$G$5000,"yes") -> 17 | G23: =COUNTIFS('Outcome diagnoses'!$A$5:$A$5000,"AF",'Outcome diagnoses'!$G$5:$G$5000,"yes") -> 15
A24: Outcome ICD codes (excluded on purpose) | C24: =COUNTIFS('Outcome diagnoses'!$A$5:$A$5000,"AMI",'Outcome diagnoses'!$G$5:$G$5000,"no") -> 10 | D24: =COUNTIFS('Outcome diagnoses'!$A$5:$A$5000,"Stroke",'Outcome diagnoses'!$G$5:$G$5000,"no") -> 10 | E24: =COUNTIFS('Outcome diagnoses'!$A$5:$A$5000,"HF",'Outcome diagnoses'!$G$5:$G$5000,"no") -> 0 | F24: =COUNTIFS('Outcome diagnoses'!$A$5:$A$5000,"SCD",'Outcome diagnoses'!$G$5:$G$5000,"no") -> 0 | G24: =COUNTIFS('Outcome diagnoses'!$A$5:$A$5000,"AF",'Outcome diagnoses'!$G$5:$G$5000,"no") -> 0
A25: Evidence LOINC codes | C25: =COUNTIFS('Labs & vitals'!$A$5:$A$1000,"AMI") -> 6 | D25: =COUNTIFS('Labs & vitals'!$A$5:$A$1000,"Stroke") -> 0 | E25: =COUNTIFS('Labs & vitals'!$A$5:$A$1000,"HF") -> 4 | F25: =COUNTIFS('Labs & vitals'!$A$5:$A$1000,"SCD") -> 0 | G25: =COUNTIFS('Labs & vitals'!$A$5:$A$1000,"AF") -> 0
A26: Evidence procedure code groups | C26: =COUNTIFS(Procedures!$A$5:$A$1000,"AMI") -> 4 | D26: =COUNTIFS(Procedures!$A$5:$A$1000,"Stroke") -> 8 | E26: =COUNTIFS(Procedures!$A$5:$A$1000,"HF") -> 2 | F26: =COUNTIFS(Procedures!$A$5:$A$1000,"SCD") -> 5 | G26: =COUNTIFS(Procedures!$A$5:$A$1000,"AF") -> 3
A27: Shared baseline LOINC codes | C27: =COUNTIFS('Labs & vitals'!$A$5:$A$1000,"All 5",'Labs & vitals'!$C$5:$C$1000,"Model input (baseline)") -> 26 | D27: =COUNTIFS('Labs & vitals'!$A$5:$A$1000,"All 5",'Labs & vitals'!$C$5:$C$1000,"Model input (baseline)") -> 26 | E27: =COUNTIFS('Labs & vitals'!$A$5:$A$1000,"All 5",'Labs & vitals'!$C$5:$C$1000,"Model input (baseline)") -> 26 | F27: =COUNTIFS('Labs & vitals'!$A$5:$A$1000,"All 5",'Labs & vitals'!$C$5:$C$1000,"Model input (baseline)") -> 26 | G27: =COUNTIFS('Labs & vitals'!$A$5:$A$1000,"All 5",'Labs & vitals'!$C$5:$C$1000,"Model input (baseline)") -> 26
A28: Shared history ICD codes | C28: =COUNTA('History diagnoses'!$E$5:$E$5000) -> 752 | D28: =COUNTA('History diagnoses'!$E$5:$E$5000) -> 752 | E28: =COUNTA('History diagnoses'!$E$5:$E$5000) -> 752 | F28: =COUNTA('History diagnoses'!$E$5:$E$5000) -> 752 | G28: =COUNTA('History diagnoses'!$E$5:$E$5000) -> 752

Sheet Source tables
A1: Tables and columns read
A2: Read-only access is needed to these tables in the de-identified OMOP CDM and the native FACT tables. Please confirm the Spark catalog and schema names (Open confirmations #2).
A4: Table | B4: Model | C4: Columns read | D4: Calculators | E4: Used for | F4: Access needed
A5: person | B5: OMOP CDM | C5: person_id, gender_concept_id, year/month/day_of_birth, birth_datetime, race_concept_id, ethnicity_concept_id | D5: All 5 | E5: Demographics, eligibility | F5: Yes
A6: observation_period | B6: OMOP CDM | C6: person_id, observation_period_start_date, observation_period_end_date | D6: All 5 | E6: Eligibility, follow-up | F6: Yes
A7: visit_occurrence | B7: OMOP CDM | C7: visit_occurrence_id, person_id, visit_concept_id, visit_start_date, visit_end_date | D7: All 5 | E7: Index visit; acute setting | F7: Yes
A8: condition_occurrence | B8: OMOP CDM | C8: person_id, condition_concept_id, condition_source_concept_id, condition_source_value, condition_start_date, condition_status_concept_id, condition_type_concept_id, visit_occurrence_id | D8: All 5 | E8: History flags; outcome candidates | F8: Yes
A9: observation | B9: OMOP CDM | C9: person_id, observation_concept_id, observation_source_concept_id, observation_source_value, observation_date | D9: All 5 | E9: History Z/V codes (family history, smoking, prior stroke) | F9: Yes
A10: measurement | B10: OMOP CDM | C10: measurement_id, person_id, measurement_concept_id, measurement_date, measurement_datetime, value_as_number, unit_concept_id, unit_source_value, range_high | D10: All 5 | E10: Labs/vitals; troponin, BNP evidence | F10: Yes
A11: procedure_occurrence | B11: OMOP CDM | C11: person_id, procedure_concept_id, procedure_source_concept_id, procedure_source_value, procedure_date | D11: All 5 | E11: Adjudication evidence | F11: Yes
A12: drug_exposure | B12: OMOP CDM | C12: person_id, drug_concept_id, drug_exposure_start_date, drug_exposure_end_date | D12: All 5 | E12: Medication flags | F12: Yes
A13: death | B13: OMOP CDM | C13: person_id, death_date, cause_concept_id | D13: All 5 | E13: Exclusion, censoring, SCD evidence | F13: Yes
A14: note | B14: OMOP CDM | C14: note_id, person_id, note_date, note_title, note_text | D14: All 5 | E14: CAC, LVEF, event-window notes (includes FACT_RADIOLOGY reports) | F14: Yes
A15: concept | B15: OMOP vocabulary | C15: concept_id, concept_code, vocabulary_id, concept_name, domain_id | D15: All 5 | E15: Code look-up | F15: Yes
... A18: FACT_RADIOLOGY | B18: Mayo native | C18: RADIOLOGY_REPORT (already in OMOP note.note_text) | D18: All 5 | E18: Only if OMOP note does not hold every report | F18: Confirm

Sheet Labs & vitals
A1: Labs and vitals (OMOP measurement, LOINC)
A2: Baseline values are the latest in the look-back window, harmonised to the units shown. Evidence labs are pulled for every result after index and read around each candidate event.
A4: Calculators | B4: Data element | C4: Purpose | D4: Vocabulary | E4: Code | F4: LOINC name | G4: Unit | H4: OMOP table | I4: Time window | J4: Notes
A5: All 5 | B5: Height | C5: Model input (baseline) | D5: LOINC | E5: 8302-2 | F5: Body height | G5: cm | H5: measurement | I5: Latest value in the 730 days up to and including index
A6: All 5 | B6: Height | C6: Model input (baseline) | D6: LOINC | E6: 3137-7 | F6: Body height Measured | G6: cm | H6: measurement | I6: Latest value in the 730 days up to and including index
A7: All 5 | B7: Weight | C7: Model input (baseline) | D7: LOINC | E7: 29463-7 | F7: Body weight | G7: kg | H7: measurement | I7: Latest value in the 730 days up to and including index
A8: All 5 | B8: Weight | C8: Model input (baseline) | D8: LOINC | E8: 3141-9 | F8: Body weight Measured | G8: kg | H8: measurement | I8: Latest value in the 730 days up to and including index
A9: All 5 | B9: BMI | C9: Model input (baseline) | D9: LOINC | E9: 39156-5 | F9: Body mass index (BMI) [Ratio] | G9: kg/m² | H9: measurement | I9: Latest value in the 730 days up to and including index | J9: BMI is also computed from height and weight
A10: All 5 | B10: Systolic BP | C10: Model input (baseline) | D10: LOINC | E10: 8480-6 | F10: Systolic blood pressure | G10: mmHg | H10: measurement | I10: Latest value in the 730 days up to and including index
A11: All 5 | B11: Systolic BP | C11: Model input (baseline) | D11: LOINC | E11: 8459-0 | F11: Systolic blood pressure--sitting | G11: mmHg | H11: measurement | I11: Latest value in the 730 days up to and including index
A12: All 5 | B12: Diastolic BP | C12: Model input (baseline) | D12: LOINC | E12: 8462-4 | F12: Diastolic blood pressure | G12: mmHg | H12: measurement | I12: Latest value in the 730 days up to and including index
A13: All 5 | B13: Diastolic BP | C13: Model input (baseline) | D13: LOINC | E13: 8453-3 | F13: Diastolic blood pressure--sitting | G13: mmHg | H13: measurement | I13: Latest value in the 730 days up to and including index
A14: All 5 | B14: Total Cholesterol | C14: Model input (baseline) | D14: LOINC | E14: 2093-3 | F14: Cholesterol [Mass/volume] in Serum or Plasma | G14: mg/dL | H14: measurement | I14: Latest value in the 730 days up to and including index
A15: All 5 | B15: HDL Cholesterol | C15: Model input (baseline) | D15: LOINC | E15: 2085-8 | F15: Cholesterol in HDL [Mass/volume] in Serum or Plasma | G15: mg/dL | H15: measurement | I15: Latest value in the 730 days up to and including index
A16: All 5 | B16: LDL Cholesterol | C16: Model input (baseline) | D16: LOINC | E16: 13457-7 | F16: Cholesterol in LDL [Mass/volume] in Serum or Plasma by calculation | G16: mg/dL | H16: measurement | I16: Latest value in the 730 days up to and including index
A17: All 5 | B17: LDL Cholesterol | C17: Model input (baseline) | D17: LOINC | E17: 18262-6 | F17: Cholesterol in LDL [Mass/volume] in Serum or Plasma by Direct assay | G17: mg/dL | H17: measurement | I17: Latest value in the 730 days up to and including index
A18: All 5 | B18: LDL Cholesterol | C18: Model input (baseline) | D18: LOINC | E18: 2089-1 | F18: Cholesterol in LDL [Mass/volume] in Serum or Plasma | G18: mg/dL | H18: measurement | I18: Latest value in the 730 days up to and including index
A19: All 5 | B19: Triglycerides | C19: Model input (baseline) | D19: LOINC | E19: 2571-8 | F19: Triglyceride [Mass/volume] in Serum or Plasma | G19: mg/dL | H19: measurement | I19: Latest value in the 730 days up to and including index
A20: All 5 | B20: Fasting Glucose | C20: Model input (baseline) | D20: LOINC | E20: 1558-6 | F20: Fasting glucose [Mass/volume] in Serum or Plasma | G20: mg/dL | H20: measurement | I20: Latest value in the 730 days up to and including index
A21: All 5 | B21: Fasting Glucose | C21: Model input (baseline) | D21: LOINC | E21: 2345-7 | F21: Glucose [Mass/volume] in Serum or Plasma | G21: mg/dL | H21: measurement | I21: Latest value in the 730 days up to and including index
... A30: All 5 | B30: eGFR | C30: Model input (baseline) | D30: LOINC | E30: 48643-1 | F30: eGFR (MDRD) among blacks | G30: mL/min/1.73m² | H30: measurement | I30: Latest value in the 730 days up to and including index
A31: All 5 | B31: Total Cholesterol | C31: Eligibility (I4) | D31: LOINC | E31: 2093-3 | F31: Cholesterol [Mass/volume] in Serum or Plasma | G31: mg/dL | H31: measurement | I31: Any value in the 365 days before index | J31: Inclusion I4: total or HDL cholesterol measured
A32: All 5 | B32: HDL Cholesterol | C32: Eligibility (I4) | D32: LOINC | E32: 2085-8 | F32: Cholesterol in HDL [Mass/volume] in Serum or Plasma | G32: mg/dL | H32: measurement | I32: Any value in the 365 days before index | J32: Inclusion I4: total or HDL cholesterol measured
A33: AMI | B33: Troponin I | C33: Adjudication evidence (after index) | D33: LOINC | E33: 10839-9 | F33: Troponin I.cardiac [Mass/volume] in Serum or Plasma | G33: ng/L or ng/mL (converted to ng/L) | H33: measurement (incl. range_high) | I33: All results after index; reviewed -1 to +3 days around each candidate event | J33: range_high is used as the upper reference limit when present
A34: AMI | B34: Troponin I | C34: Adjudication evidence (after index) | D34: LOINC | E34: 42757-5 | F34: Troponin I.cardiac [Mass/volume] in Blood | G34: ng/L or ng/mL (converted to ng/L) | H34: measurement (incl. range_high) | I34: All results after index; reviewed -1 to +3 days around each candidate event | J34: range_high is used as the upper reference limit when present
A35: AMI | B35: Troponin I | C35: Adjudication evidence (after index) | D35: LOINC | E35: 49563-0 | F35: Troponin I.cardiac [Mass/volume] in Serum or Plasma by Detection limit <= 0.01 ng/mL | G35: ng/L or ng/mL (converted to ng/L) | H35: measurement (incl. range_high) | I35: All results after index; reviewed -1 to +3 days around each candidate event | J35: range_high is used as the upper reference limit when present
A36: AMI | B36: Troponin T (conventional) | C36: Adjudication evidence (after index) | D36: LOINC | E36: 6598-7 | F36: Troponin T.cardiac [Mass/volume] in Serum or Plasma | G36: ng/L or ng/mL (converted to ng/L) | H36: measurement (incl. range_high) | I36: All results after index; reviewed -1 to +3 days around each candidate event | J36: range_high is used as the upper reference limit when present
A37: AMI | B37: hs-Troponin I | C37: Adjudication evidence (after index) | D37: LOINC | E37: 89579-7 | F37: Troponin I.cardiac [Mass/volume] in Serum or Plasma by High sensitivity method | G37: ng/L or ng/mL (converted to ng/L) | H37: measurement (incl. range_high) | I37: All results after index; reviewed -1 to +3 days around each candidate event | J37: range_high is used as the upper reference limit when present
A38: AMI | B38: hs-Troponin T | C38: Adjudication evidence (after index) | D38: LOINC | E38: 67151-1 | F38: Troponin T.cardiac [Mass/volume] in Serum or Plasma by High sensitivity method (Mayo TRPS, Roche Gen 5) | G38: ng/L or ng/mL (converted to ng/L) | H38: measurement (incl. range_high) | I38: All results after index; reviewed -1 to +3 days around each candidate event | J38: range_high is used as the upper reference limit when present
A39: HF | B39: BNP | C39: Adjudication evidence (after index) | D39: LOINC | E39: 30934-4 | F39: Natriuretic peptide B [Mass/volume] in Serum or Plasma | G39: pg/mL (pmol/L converted) | H39: measurement (incl. range_high) | I39: All results after index; reviewed -2 to +3 days around each candidate event
A40: HF | B40: BNP | C40: Adjudication evidence (after index) | D40: LOINC | E40: 42637-9 | F40: Natriuretic peptide B [Mass/volume] in Blood | G40: pg/mL (pmol/L converted) | H40: measurement (incl. range_high) | I40: All results after index; reviewed -2 to +3 days around each candidate event
A41: HF | B41: NT-proBNP | C41: Adjudication evidence (after index) | D41: LOINC | E41: 33762-6 | F41: NT-proBNP [Mass/volume] in Serum or Plasma | G41: pg/mL (pmol/L converted) | H41: measurement (incl. range_high) | I41: All results after index; reviewed -2 to +3 days around each candidate event
A42: HF | B42: NT-proBNP | C42: Adjudication evidence (after index) | D42: LOINC | E42: 83107-3 | F42: NT-proBNP [Mass/volume] in Serum, Plasma or Blood by Immunoassay (Mayo PBNP1) | G42: pg/mL (pmol/L converted) | H42: measurement (incl. range_high) | I42: All results after index; reviewed -2 to +3 days around each candidate event

Sheet History diagnoses
A1: History diagnoses (every code)
A2: A flag is set when any of these codes is recorded on or before index, in condition_occurrence or observation. Expanded from the code-set patterns against the official code sets.
A4: Calculators | B4: History flag | C4: Purpose | D4: Vocabulary | E4: Code | F4: Description | G4: Status | H4: OMOP table | I4: Time window
A5: All 5 | B5: Prior MI | C5: Model input (history flag) | D5: ICD10CM | E5: I21 | F5: Acute myocardial infarction | G5: header | H5: condition_occurrence + observation | I5: Any time on or before index
A6: All 5 | B6: Prior MI | C6: Model input (history flag) | D6: ICD10CM | E6: I21.0 | F6: ST elevation (STEMI) myocardial infarction of anterior wall | G6: header | H6: condition_occurrence + observation | I6: Any time on or before index
A7: All 5 | B7: Prior MI | C7: Model input (history flag) | D7: ICD10CM | E7: I21.01 | F7: ST elevation (STEMI) myocardial infarction involving left main coronary artery | G7: billable | H7: condition_occurrence + observation | I7: Any time on or before index
A8: All 5 | B8: Prior MI | C8: Model input (history flag) | D8: ICD10CM | E8: I21.02 | F8: ST elevation (STEMI) myocardial infarction involving left anterior descending coronary artery | G8: billable | H8: condition_occurrence + observation | I8: Any time on or before index
A9: All 5 | B9: Prior MI | C9: Model input (history flag) | D9: ICD10CM | E9: I21.09 | F9: ST elevation (STEMI) myocardial infarction involving other coronary artery of anterior wall | G9: billable | H9: condition_occurrence + observation | I9: Any time on or before index
A10: All 5 | B10: Prior MI | C10: Model input (history flag) | D10: ICD10CM | E10: I21.1 | F10: ST elevation (STEMI) myocardial infarction of inferior wall | G10: header | H10: condition_occurrence + observation | I10: Any time on or before index
A11: All 5 | B11: Prior MI | C11: Model input (history flag) | D11: ICD10CM | E11: I21.11 | F11: ST elevation (STEMI) myocardial infarction involving right coronary artery | G11: billable | H11: condition_occurrence + observation | I11: Any time on or before index
A12: All 5 | B12: Prior MI | C12: Model input (history flag) | D12: ICD10CM | E12: I21.19 | F12: ST elevation (STEMI) myocardial infarction involving other coronary artery of inferior wall | G12: billable | H12: condition_occurrence + observation | I12: Any time on or before index
A13: All 5 | B13: Prior MI | C13: Model input (history flag) | D13: ICD10CM | E13: I21.2 | F13: ST elevation (STEMI) myocardial infarction of other sites | G13: header | H13: condition_occurrence + observation | I13: Any time on or before index
A14: All 5 | B14: Prior MI | C14: Model input (history flag) | D14: ICD10CM | E14: I21.21 | F14: ST elevation (STEMI) myocardial infarction involving left circumflex coronary artery | G14: billable | H14: condition_occurrence + observation | I14: Any time on or before index
A15: All 5 | B15: Prior MI | C15: Model input (history flag) | D15: ICD10CM | E15: I21.29 | F15: ST elevation (STEMI) myocardial infarction involving other sites | G15: billable | H15: condition_occurrence + observation | I15: Any time on or before index
... A756: All 5 | B756: diabetes (prediabetes) | C756: Model input (history flag) | D756: ICD9CM | E756: 790.29 | F756: Other abnormal glucose | G756: billable | H756: condition_occurrence + observation | I756: Any time on or before index

Sheet Outcome diagnoses
A1: Outcome diagnoses (candidate events)
A2: A code recorded after index creates a CANDIDATE event; auto-labelling and cardiologist adjudication decide whether it is a real event. included = no rows are deliberately not used (reason given).
A4: Calculator | B4: Vocabulary | C4: Code | D4: Description | E4: Status | F4: Subtype hint | G4: Included | H4: Reason excluded | I4: OMOP table | J4: Time window
A5: AMI | B5: ICD10CM | C5: I21 | D5: Acute myocardial infarction | E5: header (not billable in FY2026; may appear in older records) | G5: yes | I5: condition_occurrence | J5: Any date after index (models use 30-day, 1-year, 5-year horizons)
A6: AMI | B6: ICD10CM | C6: I21.0 | D6: ST elevation (STEMI) myocardial infarction of anterior wall | E6: header (not billable in FY2026; may appear in older records) | F6: stemi | G6: yes | I6: condition_occurrence | J6: Any date after index (models use 30-day, 1-year, 5-year horizons)
A7: AMI | B7: ICD10CM | C7: I21.01 | D7: ST elevation (STEMI) myocardial infarction involving left main coronary artery | E7: billable | F7: stemi | G7: yes | I7: condition_occurrence | J7: Any date after index (models use 30-day, 1-year, 5-year horizons)
A8: AMI | B8: ICD10CM | C8: I21.02 | D8: ST elevation (STEMI) myocardial infarction involving left anterior descending coronary artery | E8: billable | F8: stemi | G8: yes | I8: condition_occurrence | J8: Any date after index (models use 30-day, 1-year, 5-year horizons)
A9: AMI | B9: ICD10CM | C9: I21.09 | D9: ST elevation (STEMI) myocardial infarction involving other coronary artery of anterior wall | E9: billable | F9: stemi | G9: yes | I9: condition_occurrence | J9: Any date after index (models use 30-day, 1-year, 5-year horizons)
A10: AMI | B10: ICD10CM | C10: I21.1 | D10: ST elevation (STEMI) myocardial infarction of inferior wall | E10: header (not billable in FY2026; may appear in older records) | F10: stemi | G10: yes | I10: condition_occurrence | J10: Any date after index (models use 30-day, 1-year, 5-year horizons)
A11: AMI | B11: ICD10CM | C11: I21.11 | D11: ST elevation (STEMI) myocardial infarction involving right coronary artery | E11: billable | F11: stemi | G11: yes | I11: condition_occurrence | J11: Any date after index (models use 30-day, 1-year, 5-year horizons)
A12: AMI | B12: ICD10CM | C12: I21.19 | D12: ST elevation (STEMI) myocardial infarction involving other coronary artery of inferior wall | E12: billable | F12: stemi | G12: yes | I12: condition_occurrence | J12: Any date after index (models use 30-day, 1-year, 5-year horizons)
A13: AMI | B13: ICD10CM | C13: I21.2 | D13: ST elevation (STEMI) myocardial infarction of other sites | E13: header (not billable in FY2026; may appear in older records) | F13: stemi | G13: yes | I13: condition_occurrence | J13: Any date after index (models use 30-day, 1-year, 5-year horizons)
A14: AMI | B14: ICD10CM | C14: I21.21 | D14: ST elevation (STEMI) myocardial infarction involving left circumflex coronary artery | E14: billable | F14: stemi | G14: yes | I14: condition_occurrence | J14: Any date after index (models use 30-day, 1-year, 5-year horizons)
A15: AMI | B15: ICD10CM | C15: I21.29 | D15: ST elevation (STEMI) myocardial infarction involving other sites | E15: billable | F15: stemi | G15: yes | I15: condition_occurrence | J15: Any date after index (models use 30-day, 1-year, 5-year horizons)
A16: AMI | B16: ICD10CM | C16: I21.3 | D16: ST elevation (STEMI) myocardial infarction of unspecified site | E16: billable | F16: stemi | G16: yes | I16: condition_occurrence | J16: Any date after index (models use 30-day, 1-year, 5-year horizons)
A17: AMI | B17: ICD10CM | C17: I21.4 | D17: Non-ST elevation (NSTEMI) myocardial infarction | E17: billable | F17: nstemi | G17: yes | I17: condition_occurrence | J17: Any date after index (models use 30-day, 1-year, 5-year horizons)
A18: AMI | B18: ICD10CM | C18: I21.9 | D18: Acute myocardial infarction, unspecified | E18: billable | F18: unspecified | G18: yes | I18: condition_occurrence | J18: Any date after index (models use 30-day, 1-year, 5-year horizons)
A19: AMI | B19: ICD10CM | C19: I21.A | D19: Other type of myocardial infarction | E19: header (not billable in FY2026; may appear in older records) | G19: yes | I19: condition_occurrence | J19: Any date after index (models use 30-day, 1-year, 5-year horizons)
A20: AMI | B20: ICD10CM | C20: I21.A1 | D20: Myocardial infarction type 2 | E20: billable | F20: type2 | G20: yes | I20: condition_occurrence | J20: Any date after index (models use 30-day, 1-year, 5-year horizons)
A21: AMI | B21: ICD10CM | C21: I21.A9 | D21: Other myocardial infarction type | E21: billable | F21: unspecified | G21: yes | I21: condition_occurrence | J21: Any date after index (models use 30-day, 1-year, 5-year horizons)
A22: AMI | B22: ICD10CM | C22: I21.B | D22: Myocardial infarction with coronary microvascular dysfunction | E22: billable | F22: unspecified | G22: yes | I22: condition_occurrence | J22: Any date after index (models use 30-day, 1-year, 5-year horizons)
A23: AMI | B23: ICD10CM | C23: I22 | D23: Subsequent ST elevation (STEMI) and non-ST elevation (NSTEMI) myocardial infarction | E23: header (not billable in FY2026; may appear in older records) | G23: yes | I23: condition_occurrence | J23: Any date after index (models use 30-day, 1-year, 5-year horizons)
A24: AMI | B24: ICD10CM | C24: I22.0 | D24: Subsequent ST elevation (STEMI) myocardial infarction of anterior wall | E24: billable | F24: stemi | G24: yes | I24: condition_occurrence | J24: Any date after index (models use 30-day, 1-year, 5-year horizons)
A25: AMI | B25: ICD10CM | C25: I22.1 | D25: Subsequent ST elevation (STEMI) myocardial infarction of inferior wall | E25: billable | F25: stemi | G25: yes | I25: condition_occurrence | J25: Any date after index (models use 30-day, 1-year, 5-year horizons)
A26: AMI | B26: ICD10CM | C26: I22.2 | D26: Subsequent non-ST elevation (NSTEMI) myocardial infarction | E26: billable | F26: nstemi | G26: yes | I26: condition_occurrence | J26: Any date after index (models use 30-day, 1-year, 5-year horizons)
A27: AMI | B27: ICD10CM | C27: I22.8 | D27: Subsequent ST elevation (STEMI) myocardial infarction of other sites | E27: billable | F27: stemi | G27: yes | I27: condition_occurrence | J27: Any date after index (models use 30-day, 1-year, 5-year horizons)
A28: AMI | B28: ICD10CM | C28: I22.9 | D28: Subsequent ST elevation (STEMI) myocardial infarction of unspecified site | E28: billable | F28: stemi | G28: yes | I28: condition_occurrence | J28: Any date after index (models use 30-day, 1-year, 5-year horizons)
A29: AMI | B29: ICD9CM | C29: 410.00 | D29: Acute myocardial infarction of anterolateral wall, episode of care unspecified | E29: billable | F29: stemi | G29: yes | I29: condition_occurrence | J29: Any date after index (models use 30-day, 1-year, 5-year horizons)
A30: AMI | B30: ICD9CM | C30: 410.01 | D30: Acute myocardial infarction of anterolateral wall, initial episode of care | E30: billable | F30: stemi | G30: yes | I30: condition_occurrence | J30: Any date after index (models use 30-day, 1-year, 5-year horizons)
A31: AMI | B31: ICD9CM | C31: 410.02 | D31: Acute myocardial infarction of anterolateral wall, subsequent episode of care | E31: billable | F31: stemi | G31: no | H31: Subsequent episode of care (follow-up of an earlier MI, not a new event) | I31: condition_occurrence | J31: Any date after index (models use 30-day, 1-year, 5-year horizons)
A32: AMI | B32: ICD9CM | C32: 410.10 | D32: Acute myocardial infarction of other anterior wall, episode of care unspecified | E32: billable | F32: stemi | G32: yes | I32: condition_occurrence | J32: Any date after index (models use 30-day, 1-year, 5-year horizons)
A33: AMI | B33: ICD9CM | C33: 410.11 | D33: Acute myocardial infarction of other anterior wall, initial episode of care | E33: billable | F33: stemi | G33: yes | I33: condition_occurrence | J33: Any date after index (models use 30-day, 1-year, 5-year horizons)
A34: AMI | B34: ICD9CM | C34: 410.12 | D34: Acute myocardial infarction of other anterior wall, subsequent episode of care | E34: billable | F34: stemi | G34: no | H34: Subsequent episode of care (follow-up of an earlier MI, not a new event) | I34: condition_occurrence | J34: Any date after index (models use 30-day, 1-year, 5-year horizons)
A35: AMI | B35: ICD9CM | C35: 410.20 | D35: Acute myocardial infarction of inferolateral wall, episode of care unspecified | E35: billable | F35: stemi | G35: yes | I35: condition_occurrence | J35: Any date after index (models use 30-day, 1-year, 5-year horizons)
A36: AMI | B36: ICD9CM | C36: 410.21 | D36: Acute myocardial infarction of inferolateral wall, initial episode of care | E36: billable | F36: stemi | G36: yes | I36: condition_occurrence | J36: Any date after index (models use 30-day, 1-year, 5-year horizons)
A37: AMI | B37: ICD9CM | C37: 410.22 | D37: Acute myocardial infarction of inferolateral wall, subsequent episode of care | E37: billable | F37: stemi | G37: no | H37: Subsequent episode of care (follow-up of an earlier MI, not a new event) | I37: condition_occurrence | J37: Any date after index (models use 30-day, 1-year, 5-year horizons)
A38: AMI | B38: ICD9CM | C38: 410.30 | D38: Acute myocardial infarction of inferoposterior wall, episode of care unspecified | E38: billable | F38: stemi | G38: yes | I38: condition_occurrence | J38: Any date after index (models use 30-day, 1-year, 5-year horizons)
A39: AMI | B39: ICD9CM | C39: 410.31 | D39: Acute myocardial infarction of inferoposterior wall, initial episode of care | E39: billable | F39: stemi | G39: yes | I39: condition_occurrence | J39: Any date after index (models use 30-day, 1-year, 5-year horizons)
A40: AMI | B40: ICD9CM | C40: 410.32 | D40: Acute myocardial infarction of inferoposterior wall, subsequent episode of care | E40: billable | F40: stemi | G40: no | H40: Subsequent episode of care (follow-up of an earlier MI, not a new event) | I40: condition_occurrence | J40: Any date after index (models use 30-day, 1-year, 5-year horizons)
A41: AMI | B41: ICD9CM | C41: 410.40 | D41: Acute myocardial infarction of other inferior wall, episode of care unspecified | E41: billable | F41: stemi | G41: yes | I41: condition_occurrence | J41: Any date after index (models use 30-day, 1-year, 5-year horizons)
...

Sheet Procedures
A1: Procedures (adjudication evidence)
A2: CPT codes are listed as ranges (not every number in a range is an active CPT code). ICD-10-PCS entries ending in * mean every code starting with those characters.
A4: Calculator | B4: Procedure | C4: Vocabulary | D4: Codes | E4: Count | F4: Pattern in code set | G4: How it is used | H4: OMOP table | I4: Time window
A5: AMI | B5: Percutaneous coronary intervention | C5: CPT4 | D5: 92920–92944, 92980–92984 | E5: 30 | F5: 929(2\d|3\d|4[0-4]), 9298[0-4] | G5: Evidence (coronary_procedure vote); also creates an evidence-only candidate | H5: procedure_occurrence | I5: After index; reviewed -1 to +3 days around candidates
A6: AMI | B6: Percutaneous coronary intervention | C6: ICD10PCS | D6: 0270*, 0271*, 0272*, 0273* | E6: 4 | F6: 027[0-3] | G6: Evidence (coronary_procedure vote); also creates an evidence-only candidate | H6: procedure_occurrence | I6: After index; reviewed -1 to +3 days around candidates
A7: AMI | B7: Coronary angiography | C7: CPT4 | D7: 93454–93461, 93501, 93508 | E7: 10 | F7: 934(5[4-9]|6[01]), 9350[18] | G7: Evidence (coronary_procedure vote) | H7: procedure_occurrence | I7: After index; reviewed -1 to +3 days around candidates
A8: AMI | B8: Coronary angiography | C8: ICD10PCS | D8: B210*, B211* | E8: 2 | F8: B21[01] | G8: Evidence (coronary_procedure vote) | H8: procedure_occurrence | I8: After index; reviewed -1 to +3 days around candidates
A9: Stroke | B9: Head CT | C9: CPT4 | D9: 70450, 70460, 70470, 70496 | E9: 4 | F9: 70450, 70460, 70470, 70496 | G9: Evidence (neuroimaging vote) | H9: procedure_occurrence | I9: After index; reviewed -1 to +3 days around candidates
A10: Stroke | B10: Head CT | C10: ICD10PCS | D10: B020* | E10: 1 | F10: B020 | G10: Evidence (neuroimaging vote) | H10: procedure_occurrence | I10: After index; reviewed -1 to +3 days around candidates
A11: Stroke | B11: Head / brain MRI | C11: CPT4 | D11: 70544–70546, 70551–70553 | E11: 6 | F11: 7055[1-3], 7054[4-6] | G11: Evidence (neuroimaging vote) | H11: procedure_occurrence | I11: After index; reviewed -1 to +3 days around candidates
A12: Stroke | B12: Head / brain MRI | C12: ICD10PCS | D12: B030* | E12: 1 | F12: B030 | G12: Evidence (neuroimaging vote) | H12: procedure_occurrence | I12: After index; reviewed -1 to +3 days around candidates
A13: HF | B13: Echocardiogram | C13: CPT4 | D13: 93303–93308, 93312–93318, 93350–93351 | E13: 15 | F13: 9330[3-8], 9331[2-8], 9335[01] | G13: Evidence (echo vote; LVEF for HFrEF/HFpEF subtype) | H13: procedure_occurrence | I13: After index; reviewed -2 to +3 days around candidates
A14: HF | B14: Echocardiogram | C14: ICD10PCS | D14: B24* | E14: 1 | F14: B24 | G14: Evidence (echo vote; LVEF for HFrEF/HFpEF subtype) | H14: procedure_occurrence | I14: After index; reviewed -2 to +3 days around candidates
A15: Stroke | B15: Thrombolysis | C15: CPT4 | D15: 37195 | E15: 1 | F15: 37195 | G15: Evidence (reperfusion vote); also creates an evidence-only candidate | H15: procedure_occurrence | I15: After index; reviewed -1 to +3 days around candidates
A16: Stroke | B16: Thrombolysis | C16: ICD10PCS | D16: 3E03317 | E16: 1 | F16: 3E03317 | G16: Evidence (reperfusion vote); also creates an evidence-only candidate | H16: procedure_occurrence | I16: After index; reviewed -1 to +3 days around candidates
... A26: AF | B26: Cardiac surgery (CABG, valve replacement) | C26: ICD10PCS | D26: 02100*, 02110*, 02120*, 02130*, 02RF0*, 02RG0*, 02RH0*, 02RJ0* | E26: 8 | F26: 021[0-3]0, 02R[FGHJ]0 | G26: Rule O2: AF ≤ 30 days after cardiac surgery is post-operative, not new-onset | H26: procedure_occurrence | I26: After index; 30 days before an AF candidate

Sheet Medications
A1: Medications (OMOP drug_exposure)
A2: ATC classes are mapped to every descendant RxNorm concept in the workspace (concept_ancestor), so no RxNorm list is needed from MCP.
A4: Calculators | B4: Data element | C4: Vocabulary | D4: ATC code | E4: ATC class | F4: OMOP table / mapping | G4: Time window | H4: Notes
A5: All 5 | B5: Statin | C5: ATC | D5: C10AA | E5: HMG CoA reductase inhibitors (statins) | F5: drug_exposure (RxNorm concepts that descend from the ATC class via concept_ancestor) | G5: Any exposure in the 365 days before index | H5: Ingredient-level mapping; all routes and formulations
A6: All 5 | B6: Statin | C6: ATC | D6: C10BA | E6: Statin combinations with other lipid-modifying agents | F6: drug_exposure (RxNorm concepts that descend from the ATC class via concept_ancestor) | G6: Any exposure in the 365 days before index | H6: Ingredient-level mapping; all routes and formulations
A7: All 5 | B7: Statin | C7: ATC | D7: C10BX | E7: Statins, other combinations | F7: drug_exposure (RxNorm concepts that descend from the ATC class via concept_ancestor) | G7: Any exposure in the 365 days before index | H7: Ingredient-level mapping; all routes and formulations
A8: All 5 | B8: Aspirin | C8: ATC | D8: B01AC06 | E8: Acetylsalicylic acid (aspirin) | F8: drug_exposure (RxNorm concepts that descend from the ATC class via concept_ancestor) | G8: Any exposure in the 365 days before index | H8: Ingredient-level mapping; all routes and formulations
A9: All 5 | B9: ACE-I/ARB | C9: ATC | D9: C09 | E9: Agents acting on the renin–angiotensin system (ACE inhibitors, ARBs) | F9: drug_exposure (RxNorm concepts that descend from the ATC class via concept_ancestor) | G9: Any exposure in the 365 days before index | H9: Ingredient-level mapping; all routes and formulations
A10: All 5 | B10: Beta Blocker | C10: ATC | D10: C07 | E10: Beta-blocking agents | F10: drug_exposure (RxNorm concepts that descend from the ATC class via concept_ancestor) | G10: Any exposure in the 365 days before index | H10: Ingredient-level mapping; all routes and formulations
A11: All 5 | B11: Anticoagulant | C11: ATC | D11: B01AA | E11: Vitamin K antagonists (e.g. warfarin) | F11: drug_exposure (RxNorm concepts that descend from the ATC class via concept_ancestor) | G11: Any exposure in the 365 days before index | H11: Ingredient-level mapping; all routes and formulations
A12: All 5 | B12: Anticoagulant | C12: ATC | D12: B01AE | E12: Direct thrombin inhibitors (e.g. dabigatran) | F12: drug_exposure (RxNorm concepts that descend from the ATC class via concept_ancestor) | G12: Any exposure in the 365 days before index | H12: Ingredient-level mapping; all routes and formulations
A13: All 5 | B13: Anticoagulant | C13: ATC | D13: B01AF | E13: Direct factor Xa inhibitors (e.g. apixaban, rivaroxaban) | F13: drug_exposure (RxNorm concepts that descend from the ATC class via concept_ancestor) | G13: Any exposure in the 365 days before index | H13: Ingredient-level mapping; all routes and formulations
A14: All 5 | B14: Any antihypertensive | C14: ATC | D14: C02 | E14: Antihypertensives (centrally/peripherally acting) | F14: drug_exposure (RxNorm concepts that descend from the ATC class via concept_ancestor) | G14: Any exposure in the 365 days before index | H14: Ingredient-level mapping; all routes and formulations
A15: All 5 | B15: Any antihypertensive | C15: ATC | D15: C03 | E15: Diuretics | F15: drug_exposure (RxNorm concepts that descend from the ATC class via concept_ancestor) | G15: Any exposure in the 365 days before index | H15: Ingredient-level mapping; all routes and formulations
... A18: All 5 | B18: Any antihypertensive | C18: ATC | D18: C09 | E18: Agents acting on the renin–angiotensin system (ACE inhibitors, ARBs) | F18: drug_exposure (RxNorm concepts that descend from the ATC class via concept_ancestor) | G18: Any exposure in the 365 days before index | H18: Ingredient-level mapping; all routes and formulations

Sheet Notes & reports
A1: Clinical notes and reports
A2: Notes are read only inside the workspace (keyword prefilter in SQL, NLP in Python). Note text never leaves the workspace.
A4: Calculators | B4: Data element | C4: Purpose | D4: Source | E4: Columns | F4: Time window | G4: Text filter | H4: Note types
A5: All 5 | B5: Coronary artery calcium (Agatston) | C5: Model input (baseline) | D5: OMOP note (radiology reports = FACT_RADIOLOGY.RADIOLOGY_REPORT) | E5: note_id, person_id, note_date, note_title, note_text | F5: 730 days up to index | G5: Text filter: agatston | calcium score | H5: Radiology reports
A6: All 5 | B6: LV ejection fraction | C6: Model input (baseline) | D6: OMOP note + native FACT_ECHO_TEST.ECHO_NOTE | E6: ECHO_NOTE (confirmed); patient key, echo date, echo id (to confirm) | F6: 730 days up to index | G6: Text filter: ejection fraction | lvef | H6: Echo and imaging reports
A7: AMI, Stroke, HF, SCD, AF | B7: Event-window clinical notes | C7: Adjudication evidence | D7: OMOP note | E7: note_id, person_id, note_date, note_title, note_text | F7: −3 to +30 days around each candidate (labelling reads AMI -1 to +7; Stroke -1 to +7; HF -2 to +7; SCD -1 to +7; AF -3 to +30) | G7: Keyword prefilter: infarct|stemi|troponin|acute coronary|stroke|cva|hemorrhage|transient ischemic|tia|heart failure|chf|ejection fraction|lvef|bnp|diuresis|cardiac arrest|rosc|ventricular (fibrillation|tachycardia)|vf|vt|nsvt|atrial fib|atrial flutter|afib | H7: Discharge summaries, progress notes, ED notes, imaging reports
A8: HF | B8: Event-window echo reports | C8: Adjudication evidence (HFrEF / HFpEF subtype) | D8: native FACT_ECHO_TEST.ECHO_NOTE | E8: as above | F8: -7 to +30 days around each candidate | G8: None (all echo reports in the window) | H8: Echo reports
A9: Stroke | B9: Neuroimaging reports | C9: Adjudication evidence | D9: OMOP note (FACT_RADIOLOGY) | E9: as above | F9: −3 to +30 days around each candidate | G9: Keyword prefilter (as above) | H9: Head CT / MRI reports: infarct, hemorrhage, negative study

Sheet Concepts & demographics
A1: Person, visit, death and status concepts
A2: Concept IDs are standard OMOP concepts; please confirm the primary-diagnosis status values (Open confirmations #3).
A4: Calculators | B4: Data element | C4: OMOP table | D4: Columns | E4: Concept IDs / values | F4: Window | G4: Used for
A5: All 5 | B5: Age | C5: person | D5: year_of_birth, month_of_birth, day_of_birth (birth_datetime) | E5: — | F5: Age at index; eligible 18–89 | G5: Model input; eligibility I1/E1/E2
A6: All 5 | B6: Sex | C6: person | D6: gender_concept_id | E6: 8507 = male, 8532 = female | F6: Others excluded (E3) | G6: Model input; eligibility I5
A7: All 5 | B7: Race | C7: person | D7: race_concept_id | E7: 8527 = white, 8516 = black, 8515 = asian; any other = other | G7: Model input
A8: All 5 | B8: Ethnicity | C8: person | D8: ethnicity_concept_id | E8: 38003563 = Hispanic or Latino (→ race 'hispanic') | G8: Model input
A9: All 5 | B9: Index visit | C9: visit_occurrence | D9: visit_occurrence_id, visit_concept_id, visit_start_date | E9: 9202 = outpatient visit | F9: 2012-01-01 to 2019-12-31; one random eligible visit per patient | G9: Eligibility I2
A10: AMI, Stroke, HF, SCD | B10: Acute care setting of a candidate | C10: visit_occurrence | D10: visit_concept_id, visit_start_date, visit_end_date | E10: 9201 = inpatient, 9203 = emergency room, 262 = ER and inpatient | F10: Visit containing the candidate code | G10: Adjudication evidence (acute_visit vote)
A11: All 5 | B11: Observation time | C11: observation_period | D11: observation_period_start_date, observation_period_end_date | E11: — | F11: ≥ 365 days before index; > 0 days after | G11: Eligibility I3/E5; follow-up and censoring
A12: All 5 | B12: Death | C12: death | D12: death_date, cause_concept_id | E12: — | F12: Any date | G12: Exclusion E4; censoring; SCD evidence (death within 1 day)
A13: AMI, Stroke, HF, SCD | B13: Primary diagnosis | C13: condition_occurrence | D13: condition_status_concept_id (or condition_type_concept_id) | E13: 32901, 32902 = primary / principal (to confirm with MCP) | F13: Candidate code rows | G13: Adjudication evidence (primary_dx vote)
A14: All 5 | B14: Diagnosis codes | C14: condition_occurrence; observation | D14: *_concept_id, *_source_concept_id, *_source_value, *_date, visit_occurrence_id | E14: ICD10CM, ICD9CM source concepts | F14: See History and Outcome tabs | G14: History flags; outcome candidates
A15: All 5 | B15: Code look-up | C15: concept; concept_ancestor | D15: concept_id, concept_code, vocabulary_id, concept_name; ancestor/descendant ids | E15: Vocabularies: ICD10CM, ICD9CM, LOINC, CPT4, ICD10PCS, ATC, RxNorm, UCUM | F15: — | G15: Maps every code in this workbook to concept_ids
A16: All 5 | B16: Measurement units | C16: measurement; concept | D16: unit_concept_id, unit_source_value, value_as_number, range_high | E16: UCUM | F16: — | G16: Unit harmonisation (e.g. cholesterol mmol/L → mg/dL)

Sheet Eligibility
A1: Inclusion and exclusion criteria
A2: Adults 18–89 only; pediatric patients (under 18) are excluded from training, validation and use.
A4: ID | B4: Type | C4: Criterion | D4: Applies to | E4: Lower bound | F4: Upper bound | G4: Enforced in
A5: I1 | B5: Inclusion | C5: Age 18–89 years at the index visit (age ≥ 18.0 and < 90.0) | D5: All 5 calculators | E5: 18 years (inclusive) | F5: 89 years (inclusive; < 90) | G5: cohort SQL; API validation
A6: I2 | B6: Inclusion | C6: An outpatient visit between 2012-01-01 and 2019-12-31 (one index visit per patient, chosen at random among eligible visits) | D6: All 5 calculators | G6: cohort SQL
A7: I3 | B7: Inclusion | C7: At least 365 days of observation before the index visit | D7: All 5 calculators | G7: cohort SQL
A8: I4 | B8: Inclusion | C8: Total cholesterol or HDL cholesterol measured in the 365 days before the index visit | D8: All 5 calculators | G8: cohort SQL
A9: I5 | B9: Inclusion | C9: Recorded sex male or female (the models and published equations are sex-specific) | D9: All 5 calculators | G9: cohort SQL; API validation
A10: E1 | B10: Exclusion | C10: Age under 18 at the index visit (pediatric) | D10: All 5 calculators | F10: < 18 years | G10: cohort SQL; audit (fail); API refuses
A11: E2 | B11: Exclusion | C11: Age 90 or over at the index visit (top-coded in de-identified data) | D11: All 5 calculators | E11: ≥ 90 years | G11: cohort SQL; audit (fail); API refuses
A12: E3 | B12: Exclusion | C12: Sex not recorded as male or female | D12: All 5 calculators | G12: cohort SQL
A13: E4 | B13: Exclusion | C13: Death recorded on or before the index date | D13: All 5 calculators | G13: cohort SQL
A14: E5 | B14: Exclusion | C14: No observation time after the index date (no follow-up) | D14: All 5 calculators | G14: cohort SQL
A15: E6 | B15: Exclusion | C15: Known atrial fibrillation or flutter at the index visit | D15: Atrial Fibrillation | G15: AF training labels; API returns 'not applicable'
A16: O1 | B16: Outcome rule | C16: Type 2 (supply/demand) MI is not counted as an AMI event (the patient stays in the cohort) | D16: AMI | G16: Labelling governance (data/governance.json)
A17: O2 | B17: Outcome rule | C17: Post-operative AF (≤ 30 days after cardiac surgery) is not counted as new-onset AF (the patient stays in the cohort) | D17: AF | G17: Labelling governance (data/governance.json)
A18: O3 | B18: Outcome rule | C18: Only the first event of each outcome after the index date is counted (the patient stays in the cohort) | D18: All 5 calculators | G18: Labelling governance (data/governance.json)
A19: R | B19: Reference equation range | C19: Pooled Cohort Equations: validated 40–79 years; outside it the app shows the equation as not applicable | D19: Reference only | G19: cardioai_core/equations.py
A20: R | B20: Reference equation range | C20: CHARGE-AF: validated 46–94 years (used here up to 89); outside it the app shows the equation as not applicable | D20: Reference only | G20: cardioai_core/equations.py
A21: R | B21: Reference equation range | C21: CHA₂DS₂-VASc: validated adults with AF; outside it the app shows the equation as not applicable | D21: Reference only | G21: cardioai_core/equations.py
A22: R | B22: Reference equation range | C22: ICD criteria: validated adults; outside it the app shows the equation as not applicable | D22: Reference only | G22: cardioai_core/equations.py

Sheet Python packages
A1: Python packages imported by the code
A2: Install with: pip install -r requirements-training.txt (pyspark comes from the workspace Spark runtime). 'Installed, not used' packages come in through requirements.txt for the web app.
A4: Package | B4: Version | C4: What it is for | D4: Imported by | E4: Workspace need | F4: Notes
A5: pyspark | B5: Workspace Spark runtime (do not pip install) | C5: Spark SQL extraction from OMOP / FACT tables | D5: training/extract.py | E5: Required | F5: Provided by MCP; tested with Spark 4.0.1
A6: pyarrow | B6: >=17 | C6: Fast Spark → pandas transfer (spark.sql.execution.arrow) | D6: training/extract.py | E6: Required | F6: requirements-training.txt
A7: numpy | B7: 2.5.3 | C7: Numerical work | D7: training/*, curation/*, cardioai_core/bundle.py | E7: Required | F7: requirements.txt
A8: pandas | B8: 3.0.5 | C8: Data frames for extracts, labels, audit | D8: training/*, curation/* | E8: Required | F8: requirements.txt
A9: scikit-learn | B9: 1.9.1 | C9: Model training and calibration | D9: training/train.py, cardioai_core/bundle.py, curation/pipeline.py | E9: Required | F9: requirements.txt (import name sklearn)
A10: joblib | B10: 1.6.0 | C10: Saving the model bundle | D10: training/train.py, cardioai_core/bundle.py | E10: Required | F10: requirements.txt
A11: sqlalchemy | B11: 2.1.5 | C11: Curation workbench store (local SQLite in the workspace) | D11: curation/* | E11: Required | F11: requirements.txt
A12: fastapi | B12: 0.146.0 | C12: Curation workbench web server (127.0.0.1 only) | D12: curation/server.py | E12: Required | F12: requirements.txt
A13: uvicorn[standard] | B13: 0.53.0 | C13: Runs the curation workbench | D13: curation/server.py | E13: Required | F13: requirements.txt
A14: pydantic | B14: (installed with fastapi) | C14: Request validation in the workbench | D14: curation/server.py | E14: Required | F14: dependency of fastapi
A15: PyJWT | B15: 2.14.0 | C15: Workbench sign-in tokens | D15: curation/server.py, cardioai_core/security.py | E15: Required | F15: requirements.txt (import name jwt)
... A24: Python standard library | B24: Python 3.12 | C24: argparse, csv, json, re, math, datetime, hashlib, hmac, secrets, logging, pathlib, decimal, dataclasses, functools, collections, shutil, getpass, base64, io, copy | D24: all | E24: Required | F24: Python ≥ 3.11; tested on 3.12

Sheet Open confirmations
A1: Questions that need MCP's answer
A2: Yellow cells are for MCP: fill in the response, who answered and when.
A4: # | B4: Topic | C4: Question for MCP | D4: Why it matters | E4: What it blocks / where it is used | F4: Needed by | G4: Status | H4: MCP response | I4: Answered by / date
A5: 1 | B5: Echo data (FACT_ECHO_TEST) | C5: Which columns hold the patient key, the echo date/time and the echo id, and how does the patient key map to OMOP person_id? | D5: LVEF from echo notes is an input and an HF subtype source; the extract must join echo notes to the cohort. | E5: Echo extraction refuses to run until set (training/native_sources.json). Runbook Phase 2. | F5: Before extraction (Phase 3) | G5: Open
A6: 2 | B6: Table locations | C6: What are the Spark catalog/schema names for the OMOP CDM tables and the native FACT_* tables? Does OMOP note hold all FACT_RADIOLOGY reports? | D6: The Spark SQL extract needs exact table names; radiology reports supply CAC and stroke imaging evidence. | E6: Extraction configuration (training/extract.py, preflight). Runbook Phase 2. | F6: Before extraction (Phase 3) | G6: Open
A7: 3 | B7: Primary diagnosis | C7: Which condition_status_concept_id / condition_type_concept_id values mark a primary (principal) diagnosis in Mayo's OMOP data? | D7: The 'primary_dx' labelling function votes for events coded as primary. | E7: Auto-labelling accuracy for AMI, stroke, HF and SCD (training/codesets.py PRIMARY_STATUS). | F7: Before labelling (Phase 5) | G7: Open
A8: 4 | B8: Troponin assay history | C8: On what date did Mayo switch from conventional troponin T to hs-troponin T Gen 5, and is measurement.range_high populated? | D8: AMI labels depend on troponin above the upper reference limit with a rise/fall; the limit differs by assay. | E8: AMI auto-labels and the reference limits shown to readers. | F8: Before labelling (Phase 5) | G8: Open
A9: 5 | B9: Death data completeness | C9: How complete is death data for deaths outside Mayo (e.g. state death-index linkage), and from what date? | D9: Sudden cardiac death outside hospital is otherwise under-captured; death also censors follow-up. | E9: SCD endpoint validity; follow-up and censoring for all calculators. | F9: Before training (Phase 9) | G9: Open
A10: 6 | B10: Model export review | C10: Is the cell-suppression threshold < 11 correct, and what are the export-review steps, reviewers and expected turnaround? | D10: Only the reviewed model bundle (weights + aggregate metrics) may leave the workspace. | E10: Release of the trained bundle to Render (Runbook Phase 10). | F10: Before deployment (Phase 10) | G10: Open
A11: 7 | B11: Hosting the exported model | C11: Does the CardioAI agreement allow hosting the export-approved model bundle in private object storage and serving it from the Render web app? | D11: The live calculators load the bundle from MODEL_BUNDLE_URL. | E11: Switching the live app from demo to Mayo-trained models. | F11: Before deployment (Phase 10) | G11: Open
A12: 8 | B12: Annotator seats | C12: Are the 5 annotator seats (cardioailive.com accounts) separate from the data scientists' workspace seats? | D12: Staffing for adjudication: up to 5 cardiologist readers plus data scientists. | E12: Reader accounts in the curation workbench (reader_policy). | F12: Before adjudication (Phase 7) | G12: Open
A13: 9 | B13: Training in the workspace | C13: May the synthetic-data training environment and a second curation workbench (port 8091, localhost via JupyterLab) run in the workspace, and may annotator seats be used for training before live adjudication? | D13: The Label & Annotation Training Program runs inside the workspace on synthetic data. | E13: Training sessions 1-8 and reader certification. | F13: Before training session 1 | G13: Open
A14: 10 | B14: Platform_Validate (optional) | C14: Is Platform_Validate available for an independent bias / sensitivity / specificity report on the trained bundle, and what does submission involve? | D14: Independent validation strengthens the clinical and regulatory case. | E14: Optional step in Runbook Phase 10. | F14: After training (optional) | G14: Open
A15: 11 | B15: Age top-coding | C15: Are ages 90 and over top-coded ("90+") in the de-identified data, and are dates of birth or ages shifted? Confirm the cohort upper bound of 89. | D15: The calculators are restricted to adults 18–89; the upper bound assumes ages ≥ 90 are top-coded. | E15: Cohort age bounds (cardioai_core/schema.py AGE_MIN / AGE_MAX). | F15: Before extraction (Phase 3) | G15: Open
