Workbook

Sheet Overview
A1: CardioAI CVD Risk Calculators — Models Sheet
A2: Generated from the repository code (cardioai_core/schema.py, training/labeling.py, training/audit.py, curation/governance.py). Counts in columns G–H are live formulas over the Inputs and Auto-labelling tabs.
A3: Calculator | B3: Target C-statistic | C3: Primary endpoint | D3: Secondary endpoints | E3: Horizons | F3: Population / eligibility | G3: Inputs used | H3: Labelling functions | I3: Published comparators | J3: Model
A4: Acute Myocardial Infarction (AMI) | B4: 0.82 | C4: Acute myocardial infarction (5-year) | D4: — | E4: 30 days, 1 year, 5 years | F4: Primary and secondary prevention populations. Adults 18–89 (no pediatric patients) at a landmark outpatient visit with a lipid result in the prior year, 2012–2019. | G4: =COUNTIF(Inputs!H:H,"Y") | H4: =COUNTIFS('Auto-labelling'!A:A,"ami",'Auto-labelling'!B:B,"<>(bias)") | I4: Pooled Cohort Equations (2013 ACC/AHA) | J4: Calibrated HistGradientBoosting per endpoint × horizon (isotonic/sigmoid, 3-fold)
A5: Stroke Risk | B5: 0.75 | C5: Any stroke or TIA (5-year) | D5: Ischemic stroke; Hemorrhagic stroke; Transient ischemic attack | E5: 30 days, 1 year, 5 years | F5: Includes AF-stroke and hemorrhagic stroke models. Adults 18–89 (no pediatric patients) at a landmark outpatient visit with a lipid result in the prior year, 2012–2019. | G5: =COUNTIF(Inputs!I:I,"Y") | H5: =COUNTIFS('Auto-labelling'!A:A,"stroke",'Auto-labelling'!B:B,"<>(bias)") | I5: CHA₂DS₂-VASc; Pooled Cohort Equations (2013 ACC/AHA) | J5: Calibrated HistGradientBoosting per endpoint × horizon (isotonic/sigmoid, 3-fold)
A6: Heart Failure | B6: 0.8 | C6: Heart failure hospitalization / diagnosis (5-year) | D6: HFrEF; HFpEF | E6: 30 days, 1 year, 5 years | F6: Separate models for HFrEF and HFpEF. Adults 18–89 (no pediatric patients) at a landmark outpatient visit with a lipid result in the prior year, 2012–2019. | G6: =COUNTIF(Inputs!J:J,"Y") | H6: =COUNTIFS('Auto-labelling'!A:A,"hf",'Auto-labelling'!B:B,"<>(bias)") | I6: — | J6: Calibrated HistGradientBoosting per endpoint × horizon (isotonic/sigmoid, 3-fold)
A7: Sudden Cardiac Death (SCD) | B7: 0.78 | C7: Cardiac arrest / VF / sustained VT (5-year) | D7: — | E7: 30 days, 1 year, 5 years | F7: Guides ICD placement decisions. Adults 18–89 (no pediatric patients) at a landmark outpatient visit with a lipid result in the prior year, 2012–2019. | G7: =COUNTIF(Inputs!K:K,"Y") | H7: =COUNTIFS('Auto-labelling'!A:A,"scd",'Auto-labelling'!B:B,"<>(bias)") | I7: ACC/AHA/HRS primary-prevention ICD criteria (screen) | J7: Calibrated HistGradientBoosting per endpoint × horizon (isotonic/sigmoid, 3-fold)
A8: Atrial Fibrillation | B8: 0.8 | C8: New-onset atrial fibrillation / flutter (5-year) | D8: — | E8: 30 days, 1 year, 5 years | F8: Enables targeted screening and early intervention. Excludes patients with AF before index. Adults 18–89 (no pediatric patients) at a landmark outpatient visit with a lipid result in the prior year, 2012–2019. | G8: =COUNTIF(Inputs!L:L,"Y") | H8: =COUNTIFS('Auto-labelling'!A:A,"af",'Auto-labelling'!B:B,"<>(bias)") | I8: CHARGE-AF (simple model) | J8: Calibrated HistGradientBoosting per endpoint × horizon (isotonic/sigmoid, 3-fold)

Sheet Eligibility
A1: Who the five calculators are for: Adults aged 18–89 years. Pediatric patients (under 18) are excluded from training, validation and use of all five calculators. The same rules are applied by the cohort SQL, the automatic audit and the calculator app (cardioai_core/schema.py → ELIGIBILITY).
A2: ID | B2: Type | C2: Criterion | D2: Applies to | E2: Lower bound | F2: Upper bound | G2: Enforced in
A3: I1 | B3: Inclusion | C3: Age 18–89 years at the index visit (age ≥ 18.0 and < 90.0) | D3: All 5 calculators | E3: 18 years (inclusive) | F3: 89 years (inclusive; < 90) | G3: cohort SQL; API validation
A4: I2 | B4: Inclusion | C4: An outpatient visit between 2012-01-01 and 2019-12-31 (one index visit per patient, chosen at random among eligible visits) | D4: All 5 calculators | G4: cohort SQL
A5: I3 | B5: Inclusion | C5: At least 365 days of observation before the index visit | D5: All 5 calculators | G5: cohort SQL
A6: I4 | B6: Inclusion | C6: Total cholesterol or HDL cholesterol measured in the 365 days before the index visit | D6: All 5 calculators | G6: cohort SQL
A7: I5 | B7: Inclusion | C7: Recorded sex male or female (the models and published equations are sex-specific) | D7: All 5 calculators | G7: cohort SQL; API validation
A8: E1 | B8: Exclusion | C8: Age under 18 at the index visit (pediatric) | D8: All 5 calculators | F8: < 18 years | G8: cohort SQL; audit (fail); API refuses
A9: E2 | B9: Exclusion | C9: Age 90 or over at the index visit (top-coded in de-identified data) | D9: All 5 calculators | E9: ≥ 90 years | G9: cohort SQL; audit (fail); API refuses
A10: E3 | B10: Exclusion | C10: Sex not recorded as male or female | D10: All 5 calculators | G10: cohort SQL
A11: E4 | B11: Exclusion | C11: Death recorded on or before the index date | D11: All 5 calculators | G11: cohort SQL
A12: E5 | B12: Exclusion | C12: No observation time after the index date (no follow-up) | D12: All 5 calculators | G12: cohort SQL
A13: E6 | B13: Exclusion | C13: Known atrial fibrillation or flutter at the index visit | D13: Atrial Fibrillation | G13: AF training labels; API returns 'not applicable'
A14: O1 | B14: Outcome rule | C14: Type 2 (supply/demand) MI is not counted as an AMI event (the patient stays in the cohort) | D14: AMI | G14: Labelling governance (data/governance.json)
A15: O2 | B15: Outcome rule | C15: Post-operative AF (≤ 30 days after cardiac surgery) is not counted as new-onset AF (the patient stays in the cohort) | D15: AF | G15: Labelling governance (data/governance.json)
A16: O3 | B16: Outcome rule | C16: Only the first event of each outcome after the index date is counted (the patient stays in the cohort) | D16: All 5 calculators | G16: Labelling governance (data/governance.json)
A17: R | B17: Reference equation range | C17: Pooled Cohort Equations: validated 40–79 years; outside it the app shows the equation as not applicable | D17: Reference only | G17: cardioai_core/equations.py
A18: R | B18: Reference equation range | C18: CHARGE-AF: validated 46–94 years (used here up to 89); outside it the app shows the equation as not applicable | D18: Reference only | G18: cardioai_core/equations.py
A19: R | B19: Reference equation range | C19: CHA₂DS₂-VASc: validated adults with AF; outside it the app shows the equation as not applicable | D19: Reference only | G19: cardioai_core/equations.py
A20: R | B20: Reference equation range | C20: ICD criteria: validated adults; outside it the app shows the equation as not applicable | D20: Reference only | G20: cardioai_core/equations.py

Sheet MCP open items
A1: Items that need a response from Mayo Clinic Platform (MCP) before or during the build. Fill in the response, who answered and when.
A2: # | B2: Topic | C2: Question for MCP | D2: Why it matters | E2: What it blocks / where it is used | F2: Needed by | G2: Status | H2: MCP response | I2: Answered by / date
A3: 1 | B3: Echo data (FACT_ECHO_TEST) | C3: Which columns hold the patient key, the echo date/time and the echo id, and how does the patient key map to OMOP person_id? | D3: LVEF from echo notes is an input and an HF subtype source; the extract must join echo notes to the cohort. | E3: Echo extraction refuses to run until set (training/native_sources.json). Runbook Phase 2. | F3: Before extraction (Phase 3) | G3: Open
A4: 2 | B4: Table locations | C4: What are the Spark catalog/schema names for the OMOP CDM tables and the native FACT_* tables? Does OMOP note hold all FACT_RADIOLOGY reports? | D4: The Spark SQL extract needs exact table names; radiology reports supply CAC and stroke imaging evidence. | E4: Extraction configuration (training/extract.py, preflight). Runbook Phase 2. | F4: Before extraction (Phase 3) | G4: Open
A5: 3 | B5: Primary diagnosis | C5: Which condition_status_concept_id / condition_type_concept_id values mark a primary (principal) diagnosis in Mayo's OMOP data? | D5: The 'primary_dx' labelling function votes for events coded as primary. | E5: Auto-labelling accuracy for AMI, stroke, HF and SCD (training/codesets.py PRIMARY_STATUS). | F5: Before labelling (Phase 5) | G5: Open
A6: 4 | B6: Troponin assay history | C6: On what date did Mayo switch from conventional troponin T to hs-troponin T Gen 5, and is measurement.range_high populated? | D6: AMI labels depend on troponin above the upper reference limit with a rise/fall; the limit differs by assay. | E6: AMI auto-labels and the reference limits shown to readers. | F6: Before labelling (Phase 5) | G6: Open
A7: 5 | B7: Death data completeness | C7: How complete is death data for deaths outside Mayo (e.g. state death-index linkage), and from what date? | D7: Sudden cardiac death outside hospital is otherwise under-captured; death also censors follow-up. | E7: SCD endpoint validity; follow-up and censoring for all calculators. | F7: Before training (Phase 9) | G7: Open
A8: 6 | B8: Model export review | C8: Is the cell-suppression threshold < 11 correct, and what are the export-review steps, reviewers and expected turnaround? | D8: Only the reviewed model bundle (weights + aggregate metrics) may leave the workspace. | E8: Release of the trained bundle to Render (Runbook Phase 10). | F8: Before deployment (Phase 10) | G8: Open
A9: 7 | B9: Hosting the exported model | C9: Does the CardioAI agreement allow hosting the export-approved model bundle in private object storage and serving it from the Render web app? | D9: The live calculators load the bundle from MODEL_BUNDLE_URL. | E9: Switching the live app from demo to Mayo-trained models. | F9: Before deployment (Phase 10) | G9: Open
A10: 8 | B10: Annotator seats | C10: Are the 5 annotator seats (cardioailive.com accounts) separate from the data scientists' workspace seats? | D10: Staffing for adjudication: up to 5 cardiologist readers plus data scientists. | E10: Reader accounts in the curation workbench (reader_policy). | F10: Before adjudication (Phase 7) | G10: Open
A11: 9 | B11: Training in the workspace | C11: May the synthetic-data training environment and a second curation workbench (port 8091, localhost via JupyterLab) run in the workspace, and may annotator seats be used for training before live adjudication? | D11: The Label & Annotation Training Program runs inside the workspace on synthetic data. | E11: Training sessions 1-8 and reader certification. | F11: Before training session 1 | G11: Open
A12: 10 | B12: Platform_Validate (optional) | C12: Is Platform_Validate available for an independent bias / sensitivity / specificity report on the trained bundle, and what does submission involve? | D12: Independent validation strengthens the clinical and regulatory case. | E12: Optional step in Runbook Phase 10. | F12: After training (optional) | G12: Open
A13: 11 | B13: Age top-coding | C13: Are ages 90 and over top-coded ("90+") in the de-identified data, and are dates of birth or ages shifted? Confirm the cohort upper bound of 89. | D13: The calculators are restricted to adults 18–89; the upper bound assumes ages ≥ 90 are top-coded. | E13: Cohort age bounds (cardioai_core/schema.py AGE_MIN / AGE_MAX). | F13: Before extraction (Phase 3) | G13: Open

Sheet Endpoints
A1: Primary = the headline risk each calculator shows; secondary = other endpoints the same calculator reports. Codes only create candidates; whether a candidate is an event is decided by auto-labelling and cardiologist adjudication.
A2: Calculator | B2: Endpoint id | C2: Role | D2: Endpoint | E2: Definition (adjudication standard) | F2: Candidate diagnosis codes | G2: What counts as an event | H2: Horizons | I2: Headline horizon
A3: AMI | B3: ami | C3: Primary | D3: Acute myocardial infarction | E3: Fourth Universal Definition of Myocardial Infarction (Thygesen K et al., Circulation 2018) | F3: ICD-10-CM: I21.01–I21.4 (STEMI, NSTEMI), I21.9, I21.A1 (type 2), I21.A9, I21.B, I22.0–I22.9 (subsequent MI) ICD-9-CM: 410.x0 and 410.x1 (episode unspecified / initial); 410.x2 subsequent episode excluded 44 codes — full list: Candidate codes tab | G3: Confirmed STEMI, NSTEMI or unspecified MI. Type 2 MI excluded (governance ami_include_type2 = false) | H3: 30d, 1y, 5y | I3: 5y
A4: Stroke | B4: any_stroke | C4: Primary | D4: Any stroke or TIA | E4: AHA/ASA updated definition of stroke (Sacco RL et al., Stroke 2013) | F4: ICD-10-CM: I60.x (SAH), I61.x (ICH), I62.9, I63.x (infarction), G45.0–G45.3, G45.8, G45.9 (TIA); excluded I62.0x subdural, I62.1 extradural, G45.4 transient global amnesia ICD-9-CM: 430, 431, 432.9, 433.x1, 434.x1, 435.x (not 435.2), 436 177 codes — full list: Candidate codes tab | G4: Any confirmed stroke / tia event, any subtype | H4: 30d, 1y, 5y | I4: 5y
A5: Stroke | B5: ischemic_stroke | C5: Secondary | D5: Ischemic stroke | E5: AHA/ASA updated definition of stroke (Sacco RL et al., Stroke 2013) | F5: ICD-10-CM: I60.x (SAH), I61.x (ICH), I62.9, I63.x (infarction), G45.0–G45.3, G45.8, G45.9 (TIA); excluded I62.0x subdural, I62.1 extradural, G45.4 transient global amnesia ICD-9-CM: 430, 431, 432.9, 433.x1, 434.x1, 435.x (not 435.2), 436 177 codes — full list: Candidate codes tab | G5: Confirmed stroke event with subtype ischemic; hemorrhagic, tia = known non-event; other/unknown subtype = unresolved | H5: 30d, 1y, 5y | I5: —
A6: Stroke | B6: hemorrhagic_stroke | C6: Secondary | D6: Hemorrhagic stroke | E6: AHA/ASA updated definition of stroke (Sacco RL et al., Stroke 2013) | F6: ICD-10-CM: I60.x (SAH), I61.x (ICH), I62.9, I63.x (infarction), G45.0–G45.3, G45.8, G45.9 (TIA); excluded I62.0x subdural, I62.1 extradural, G45.4 transient global amnesia ICD-9-CM: 430, 431, 432.9, 433.x1, 434.x1, 435.x (not 435.2), 436 177 codes — full list: Candidate codes tab | G6: Confirmed stroke event with subtype hemorrhagic; ischemic, tia = known non-event; other/unknown subtype = unresolved | H6: 30d, 1y, 5y | I6: —
A7: Stroke | B7: tia | C7: Secondary | D7: Transient ischemic attack | E7: AHA/ASA updated definition of stroke (Sacco RL et al., Stroke 2013) | F7: ICD-10-CM: I60.x (SAH), I61.x (ICH), I62.9, I63.x (infarction), G45.0–G45.3, G45.8, G45.9 (TIA); excluded I62.0x subdural, I62.1 extradural, G45.4 transient global amnesia ICD-9-CM: 430, 431, 432.9, 433.x1, 434.x1, 435.x (not 435.2), 436 177 codes — full list: Candidate codes tab | G7: Confirmed stroke event with subtype tia; hemorrhagic, ischemic = known non-event; other/unknown subtype = unresolved | H7: 30d, 1y, 5y | I7: —
A8: Heart failure | B8: hf | C8: Primary | D8: Heart failure hospitalization / diagnosis | E8: Universal Definition of Heart Failure (Bozkurt B et al., J Card Fail 2021) | F8: ICD-10-CM: I50.x, I11.0, I13.0, I13.2, I09.81 (rheumatic), I97.130–I97.131 (postprocedural) ICD-9-CM: 428.x, 402.01/.11/.91, 404.01/.03/.11/.13/.91/.93, 398.91 61 codes — full list: Candidate codes tab | G8: Any confirmed heart failure event, any subtype | H8: 30d, 1y, 5y | I8: 5y
A9: Heart failure | B9: hfref | C9: Secondary | D9: HFrEF | E9: Universal Definition of Heart Failure (Bozkurt B et al., J Card Fail 2021) | F9: ICD-10-CM: I50.x, I11.0, I13.0, I13.2, I09.81 (rheumatic), I97.130–I97.131 (postprocedural) ICD-9-CM: 428.x, 402.01/.11/.91, 404.01/.03/.11/.13/.91/.93, 398.91 61 codes — full list: Candidate codes tab | G9: Confirmed hf event with subtype hfref; hfmref, hfpef = known non-event; other/unknown subtype = unresolved | H9: 30d, 1y, 5y | I9: —
A10: Heart failure | B10: hfpef | C10: Secondary | D10: HFpEF | E10: Universal Definition of Heart Failure (Bozkurt B et al., J Card Fail 2021) | F10: ICD-10-CM: I50.x, I11.0, I13.0, I13.2, I09.81 (rheumatic), I97.130–I97.131 (postprocedural) ICD-9-CM: 428.x, 402.01/.11/.91, 404.01/.03/.11/.13/.91/.93, 398.91 61 codes — full list: Candidate codes tab | G10: Confirmed hf event with subtype hfpef; hfmref, hfref = known non-event; other/unknown subtype = unresolved | H10: 30d, 1y, 5y | I10: —
A11: SCD | B11: scd | C11: Primary | D11: Cardiac arrest / VF / sustained VT | E11: 2017 AHA/ACC/HRS Ventricular Arrhythmia and SCD Guideline definitions | F11: ICD-10-CM: I46.x (arrest), I49.01 (VF), I49.02 (V flutter), I47.2 and I47.20–I47.29 (VT), I97.120–I97.121 (postprocedural arrest) ICD-9-CM: 427.5, 427.41, 427.42, 427.1 17 codes — full list: Candidate codes tab | G11: Any confirmed sudden cardiac arrest / ventricular arrhythmia event, any subtype | H11: 30d, 1y, 5y | I11: 5y
A12: AF | B12: af | C12: Primary | D12: New-onset atrial fibrillation / flutter | E12: 2023 ACC/AHA/ACCP/HRS AF Guideline: ECG-documented AF ≥30 s | F12: ICD-10-CM: I48.0, I48.11, I48.19, I48.20, I48.21, I48.3, I48.4, I48.91, I48.92 (plus I48.1, I48.2 used before Oct 2019) ICD-9-CM: 427.31, 427.32 15 codes — full list: Candidate codes tab | G12: Confirmed new AF or flutter. Post-operative AF excluded (af_exclude_postoperative = true); patients with AF before index not eligible | H12: 30d, 1y, 5y | I12: 5y

Sheet Candidate codes
A1: Every diagnosis code that creates a candidate outcome event (314 included, 20 deliberately excluded), with the official description. Source: ICD-10-CM April 2026 and ICD-9-CM v32 (CMS). Generated from training/codelists.py; the extraction matches these codes exactly. 'header' codes are not billable today but were in older years or appear as categories.
A2: Outcome | B2: Vocabulary | C2: Code | D2: Description | E2: Status | F2: Subtype hint | G2: Included | H2: Reason excluded
A3: AMI | B3: ICD10CM | C3: I21 | D3: Acute myocardial infarction | E3: header (not billable in FY2026; may appear in older records) | G3: yes
A4: AMI | B4: ICD10CM | C4: I21.0 | D4: ST elevation (STEMI) myocardial infarction of anterior wall | E4: header (not billable in FY2026; may appear in older records) | F4: stemi | G4: yes
A5: AMI | B5: ICD10CM | C5: I21.01 | D5: ST elevation (STEMI) myocardial infarction involving left main coronary artery | E5: billable | F5: stemi | G5: yes
A6: AMI | B6: ICD10CM | C6: I21.02 | D6: ST elevation (STEMI) myocardial infarction involving left anterior descending coronary artery | E6: billable | F6: stemi | G6: yes
A7: AMI | B7: ICD10CM | C7: I21.09 | D7: ST elevation (STEMI) myocardial infarction involving other coronary artery of anterior wall | E7: billable | F7: stemi | G7: yes
A8: AMI | B8: ICD10CM | C8: I21.1 | D8: ST elevation (STEMI) myocardial infarction of inferior wall | E8: header (not billable in FY2026; may appear in older records) | F8: stemi | G8: yes
A9: AMI | B9: ICD10CM | C9: I21.11 | D9: ST elevation (STEMI) myocardial infarction involving right coronary artery | E9: billable | F9: stemi | G9: yes
A10: AMI | B10: ICD10CM | C10: I21.19 | D10: ST elevation (STEMI) myocardial infarction involving other coronary artery of inferior wall | E10: billable | F10: stemi | G10: yes
A11: AMI | B11: ICD10CM | C11: I21.2 | D11: ST elevation (STEMI) myocardial infarction of other sites | E11: header (not billable in FY2026; may appear in older records) | F11: stemi | G11: yes
A12: AMI | B12: ICD10CM | C12: I21.21 | D12: ST elevation (STEMI) myocardial infarction involving left circumflex coronary artery | E12: billable | F12: stemi | G12: yes
A13: AMI | B13: ICD10CM | C13: I21.29 | D13: ST elevation (STEMI) myocardial infarction involving other sites | E13: billable | F13: stemi | G13: yes
A14: AMI | B14: ICD10CM | C14: I21.3 | D14: ST elevation (STEMI) myocardial infarction of unspecified site | E14: billable | F14: stemi | G14: yes
A15: AMI | B15: ICD10CM | C15: I21.4 | D15: Non-ST elevation (NSTEMI) myocardial infarction | E15: billable | F15: nstemi | G15: yes
A16: AMI | B16: ICD10CM | C16: I21.9 | D16: Acute myocardial infarction, unspecified | E16: billable | F16: unspecified | G16: yes
A17: AMI | B17: ICD10CM | C17: I21.A | D17: Other type of myocardial infarction | E17: header (not billable in FY2026; may appear in older records) | G17: yes
A18: AMI | B18: ICD10CM | C18: I21.A1 | D18: Myocardial infarction type 2 | E18: billable | F18: type2 | G18: yes
A19: AMI | B19: ICD10CM | C19: I21.A9 | D19: Other myocardial infarction type | E19: billable | F19: unspecified | G19: yes
A20: AMI | B20: ICD10CM | C20: I21.B | D20: Myocardial infarction with coronary microvascular dysfunction | E20: billable | F20: unspecified | G20: yes
A21: AMI | B21: ICD10CM | C21: I22 | D21: Subsequent ST elevation (STEMI) and non-ST elevation (NSTEMI) myocardial infarction | E21: header (not billable in FY2026; may appear in older records) | G21: yes
A22: AMI | B22: ICD10CM | C22: I22.0 | D22: Subsequent ST elevation (STEMI) myocardial infarction of anterior wall | E22: billable | F22: stemi | G22: yes
A23: AMI | B23: ICD10CM | C23: I22.1 | D23: Subsequent ST elevation (STEMI) myocardial infarction of inferior wall | E23: billable | F23: stemi | G23: yes
A24: AMI | B24: ICD10CM | C24: I22.2 | D24: Subsequent non-ST elevation (NSTEMI) myocardial infarction | E24: billable | F24: nstemi | G24: yes
A25: AMI | B25: ICD10CM | C25: I22.8 | D25: Subsequent ST elevation (STEMI) myocardial infarction of other sites | E25: billable | F25: stemi | G25: yes
A26: AMI | B26: ICD10CM | C26: I22.9 | D26: Subsequent ST elevation (STEMI) myocardial infarction of unspecified site | E26: billable | F26: stemi | G26: yes
A27: AMI | B27: ICD9CM | C27: 410.00 | D27: Acute myocardial infarction of anterolateral wall, episode of care unspecified | E27: billable | F27: stemi | G27: yes
A28: AMI | B28: ICD9CM | C28: 410.01 | D28: Acute myocardial infarction of anterolateral wall, initial episode of care | E28: billable | F28: stemi | G28: yes
A29: AMI | B29: ICD9CM | C29: 410.02 | D29: Acute myocardial infarction of anterolateral wall, subsequent episode of care | E29: billable | F29: stemi | G29: no | H29: Subsequent episode of care (follow-up of an earlier MI, not a new event)
A30: AMI | B30: ICD9CM | C30: 410.10 | D30: Acute myocardial infarction of other anterior wall, episode of care unspecified | E30: billable | F30: stemi | G30: yes
A31: AMI | B31: ICD9CM | C31: 410.11 | D31: Acute myocardial infarction of other anterior wall, initial episode of care | E31: billable | F31: stemi | G31: yes
A32: AMI | B32: ICD9CM | C32: 410.12 | D32: Acute myocardial infarction of other anterior wall, subsequent episode of care | E32: billable | F32: stemi | G32: no | H32: Subsequent episode of care (follow-up of an earlier MI, not a new event)
A33: AMI | B33: ICD9CM | C33: 410.20 | D33: Acute myocardial infarction of inferolateral wall, episode of care unspecified | E33: billable | F33: stemi | G33: yes
A34: AMI | B34: ICD9CM | C34: 410.21 | D34: Acute myocardial infarction of inferolateral wall, initial episode of care | E34: billable | F34: stemi | G34: yes
A35: AMI | B35: ICD9CM | C35: 410.22 | D35: Acute myocardial infarction of inferolateral wall, subsequent episode of care | E35: billable | F35: stemi | G35: no | H35: Subsequent episode of care (follow-up of an earlier MI, not a new event)
A36: AMI | B36: ICD9CM | C36: 410.30 | D36: Acute myocardial infarction of inferoposterior wall, episode of care unspecified | E36: billable | F36: stemi | G36: yes
A37: AMI | B37: ICD9CM | C37: 410.31 | D37: Acute myocardial infarction of inferoposterior wall, initial episode of care | E37: billable | F37: stemi | G37: yes
A38: AMI | B38: ICD9CM | C38: 410.32 | D38: Acute myocardial infarction of inferoposterior wall, subsequent episode of care | E38: billable | F38: stemi | G38: no | H38: Subsequent episode of care (follow-up of an earlier MI, not a new event)
A39: AMI | B39: ICD9CM | C39: 410.40 | D39: Acute myocardial infarction of other inferior wall, episode of care unspecified | E39: billable | F39: stemi | G39: yes
A40: AMI | B40: ICD9CM | C40: 410.41 | D40: Acute myocardial infarction of other inferior wall, initial episode of care | E40: billable | F40: stemi | G40: yes
...

Sheet Inputs
A1: Inputs entered in the Render app and extracted the same way from OMOP for training. Missing optional values are handled natively by the models. Y = shown on that calculator's form.
A2: Input key | B2: Label | C2: Unit | D2: Type | E2: Allowed range / options | F2: Required | G2: Section | H2: AMI | I2: Stroke | J2: HF | K2: SCD | L2: AF | M2: Model features derived | N2: Source on Mayo Clinic Platform (training)
A3: age | B3: Age | C3: years | D3: number | E3: 18–89 (adults only; under 18 refused) | F3: Yes | G3: Demographics | H3: Y | I3: Y | J3: Y | K3: Y | L3: Y | M3: age | N3: OMOP person (birth date, gender, race, ethnicity; Hispanic ethnicity → hispanic)
A4: sex | B4: Sex | D4: select | E4: male, female | F4: Yes | G4: Demographics | H4: Y | I4: Y | J4: Y | K4: Y | L4: Y | M4: sex_male | N4: OMOP person (birth date, gender, race, ethnicity; Hispanic ethnicity → hispanic)
A5: race | B5: Race/Ethnicity | D5: select | E5: white, black, hispanic, asian, other | F5: Yes | G5: Demographics | H5: Y | I5: Y | J5: Y | K5: Y | L5: Y | M5: race_black, race_hispanic, race_asian, race_other | N5: OMOP person (birth date, gender, race, ethnicity; Hispanic ethnicity → hispanic)
A6: height_cm | B6: Height | C6: cm | D6: number | E6: 120–220 | F6: No | G6: Demographics | H6: Y | I6: Y | J6: Y | K6: Y | L6: Y | M6: height_cm, bmi | N6: OMOP measurement, LOINC 8302-2, 3137-7; latest value ≤730 d before index
A7: weight_kg | B7: Weight | C7: kg | D7: number | E7: 30–300 | F7: No | G7: Demographics | H7: Y | I7: Y | J7: Y | K7: Y | L7: Y | M7: weight_kg, bmi | N7: OMOP measurement, LOINC 29463-7, 3141-9; latest value ≤730 d before index
A8: prior_mi | B8: Prior MI | D8: bool | E8: yes / no | F8: No | G8: Clinical history | H8: Y | I8: Y | J8: Y | K8: Y | L8: Y | M8: prior_mi | N8: OMOP condition_occurrence / observation on or before index: ICD-10 I21, I22, I25.2; ICD-9 410, 412
A9: prior_stroke | B9: Prior Stroke/TIA | D9: bool | E9: yes / no | F9: No | G9: Clinical history | H9: Y | I9: Y | J9: Y | K9: Y | L9: Y | M9: prior_stroke | N9: OMOP condition_occurrence / observation on or before index: ICD-10 I60–I63, G45, Z86.73; ICD-9 430–436, V12.54
A10: angina | B10: Angina | D10: bool | E10: yes / no | F10: No | G10: Clinical history | H10: Y | I10: Y | J10: Y | K10: Y | L10: Y | M10: angina | N10: OMOP condition_occurrence / observation on or before index: ICD-10 I20; ICD-9 413
A11: heart_failure | B11: Heart Failure | D11: bool | E11: yes / no | F11: No | G11: Clinical history | H11: Y | I11: Y | J11: Y | K11: Y | L11: Y | M11: heart_failure | N11: OMOP condition_occurrence / observation on or before index: ICD-10 I50, I11.0, I13.0, I13.2; ICD-9 428
A12: afib | B12: Atrial Fibrillation | D12: bool | E12: yes / no | F12: No | G12: Clinical history | H12: Y | I12: Y | J12: Y | K12: Y | L12: Y | M12: afib | N12: OMOP condition_occurrence / observation on or before index: ICD-10 I48; ICD-9 427.3
A13: family_hx_cad | B13: Family History CAD | D13: bool | E13: yes / no | F13: No | G13: Clinical history | H13: Y | I13: Y | J13: Y | K13: Y | L13: Y | M13: family_hx_cad | N13: OMOP condition_occurrence / observation on or before index: ICD-10 Z82.49; ICD-9 V17.3
A14: hypertension | B14: Hypertension diagnosis | D14: bool | E14: yes / no | F14: No | G14: Clinical history | H14: Y | I14: Y | J14: Y | K14: Y | L14: Y | M14: hypertension | N14: OMOP condition_occurrence / observation on or before index: ICD-10 I10–I16; ICD-9 401–405
A15: pad | B15: Peripheral artery disease | D15: bool | E15: yes / no | F15: No | G15: Clinical history | H15: Y | I15: Y | J15: Y | K15: Y | L15: Y | M15: pad | N15: OMOP condition_occurrence / observation on or before index: ICD-10 I70.2, I73.9; ICD-9 440.2, 443.9
A16: sbp | B16: Systolic BP | C16: mmHg | D16: number | E16: 70–250 | F16: Yes | G16: Risk factors | H16: Y | I16: Y | J16: Y | K16: Y | L16: Y | M16: sbp | N16: OMOP measurement, LOINC 8480-6, 8459-0; latest value ≤730 d before index
A17: dbp | B17: Diastolic BP | C17: mmHg | D17: number | E17: 40–150 | F17: No | G17: Risk factors | H17: Y | I17: Y | J17: Y | K17: Y | L17: Y | M17: dbp | N17: OMOP measurement, LOINC 8462-4, 8453-3; latest value ≤730 d before index
A18: smoking | B18: Smoking Status | D18: select | E18: never, former, current | F18: No | G18: Risk factors | H18: Y | I18: Y | J18: Y | K18: Y | L18: Y | M18: smoking_former, smoking_current | N18: Diagnosis codes: current = F17.2/Z72.0 within 730 d; former = Z87.891 / older current codes
A19: diabetes | B19: Diabetes Status | D19: select | E19: none, prediabetes, type1, type2 | F19: No | G19: Risk factors | H19: Y | I19: Y | J19: Y | K19: Y | L19: Y | M19: diabetes_pre, diabetes_t1, diabetes_t2 | N19: E11 → type 2, E10 → type 1, R73.0 or HbA1c 5.7–6.4% → prediabetes; HbA1c ≥6.5% → type 2
A20: total_chol | B20: Total Cholesterol | C20: mg/dL | D20: number | E20: 80–400 | F20: No | G20: Laboratory | H20: Y | I20: Y | J20: Y | K20: Y | L20: Y | M20: total_chol, non_hdl | N20: OMOP measurement, LOINC 2093-3; latest value ≤730 d before index
A21: hdl | B21: HDL Cholesterol | C21: mg/dL | D21: number | E21: 15–120 | F21: No | G21: Laboratory | H21: Y | I21: Y | J21: Y | K21: Y | L21: Y | M21: hdl, non_hdl | N21: OMOP measurement, LOINC 2085-8; latest value ≤730 d before index
A22: ldl | B22: LDL Cholesterol | C22: mg/dL | D22: number | E22: 20–300 | F22: No | G22: Laboratory | H22: Y | I22: Y | J22: Y | K22: Y | L22: Y | M22: ldl | N22: OMOP measurement, LOINC 13457-7, 18262-6, 2089-1; latest value ≤730 d before index
A23: trig | B23: Triglycerides | C23: mg/dL | D23: number | E23: 20–1500 | F23: No | G23: Laboratory | H23: Y | I23: Y | J23: Y | K23: Y | L23: Y | M23: trig | N23: OMOP measurement, LOINC 2571-8; latest value ≤730 d before index
A24: glucose | B24: Fasting Glucose | C24: mg/dL | D24: number | E24: 40–500 | F24: No | G24: Laboratory | H24: Y | I24: Y | J24: Y | K24: Y | L24: Y | M24: glucose | N24: OMOP measurement, LOINC 1558-6, 2345-7; latest value ≤730 d before index
A25: hba1c | B25: HbA1c | C25: % | D25: number | E25: 3–18 | F25: No | G25: Laboratory | H25: Y | I25: Y | J25: Y | K25: Y | L25: Y | M25: hba1c | N25: OMOP measurement, LOINC 4548-4, 17856-6; latest value ≤730 d before index
A26: hscrp | B26: hs-CRP | C26: mg/L | D26: number | E26: 0–50 | F26: No | G26: Laboratory | H26: Y | I26: Y | J26: Y | K26: Y | L26: Y | M26: hscrp | N26: OMOP measurement, LOINC 30522-7, 1988-5; latest value ≤730 d before index
A27: egfr | B27: eGFR | C27: mL/min/1.73m² | D27: number | E27: 5–150 | F27: No | G27: Laboratory | H27: Y | I27: Y | J27: Y | K27: Y | L27: Y | M27: egfr | N27: OMOP measurement, LOINC 33914-3, 62238-1, 98979-8, 48642-3, 48643-1; latest value ≤730 d before index
A28: cac_score | B28: Coronary artery calcium (Agatston) | C28: AU | D28: number | E28: 0–5000 | F28: No | G28: Imaging | H28: Y | I28: Y | J28: Y | K28: N | L28: N | M28: cac_score_log | N28: NLP of radiology reports (OMOP note = FACT_RADIOLOGY report) ≤730 d before index
A29: lvef | B29: LV ejection fraction | C29: % | D29: number | E29: 5–85 | F29: No | G29: Imaging | H29: N | I29: N | J29: Y | K29: Y | L29: Y | M29: lvef | N29: NLP of echo notes (FACT_ECHO_TEST.ECHO_NOTE) and imaging reports ≤730 d before index
A30: statin | B30: Statin | D30: bool | E30: yes / no | F30: No | G30: Medications | H30: Y | I30: Y | J30: Y | K30: Y | L30: Y | M30: statin | N30: OMOP drug_exposure ≤365 d before index; ATC C10AA, C10BA, C10BX
A31: aspirin | B31: Aspirin | D31: bool | E31: yes / no | F31: No | G31: Medications | H31: Y | I31: Y | J31: Y | K31: Y | L31: Y | M31: aspirin | N31: OMOP drug_exposure ≤365 d before index; ATC B01AC06
A32: acei_arb | B32: ACE-I/ARB | D32: bool | E32: yes / no | F32: No | G32: Medications | H32: Y | I32: Y | J32: Y | K32: Y | L32: Y | M32: acei_arb | N32: OMOP drug_exposure ≤365 d before index; ATC C09
A33: beta_blocker | B33: Beta Blocker | D33: bool | E33: yes / no | F33: No | G33: Medications | H33: Y | I33: Y | J33: Y | K33: Y | L33: Y | M33: beta_blocker | N33: OMOP drug_exposure ≤365 d before index; ATC C07
A34: anticoagulant | B34: Anticoagulant | D34: bool | E34: yes / no | F34: No | G34: Medications | H34: Y | I34: Y | J34: Y | K34: Y | L34: Y | M34: anticoagulant | N34: OMOP drug_exposure ≤365 d before index; ATC B01AA, B01AE, B01AF
A35: antihypertensive | B35: Any antihypertensive | D35: bool | E35: yes / no | F35: No | G35: Medications | H35: Y | I35: Y | J35: Y | K35: Y | L35: Y | M35: antihypertensive | N35: OMOP drug_exposure ≤365 d before index; ATC C02, C03, C07, C08, C09

Sheet Outputs
A1: What the Render app returns for each calculation (POST /api/predict).
A2: Calculator | B2: Output | C2: Description | D2: Form | E2: Produced by
A3: AMI | B3: Primary risk | C3: 5-year probability of acute myocardial infarction (falls back to 1-year / 30-day if no 5-year model) | D3: 0–100 % | E3: AI model (calibrated gradient boosting)
A4: AMI | B4: Risk category | C4: Low <5%, Moderate 5–10%, High 10–20%, Very high ≥20% of the 5-year risk (display bands, not treatment thresholds) | D4: category | E4: App rule
A5: AMI | B5: Risk by horizon | C5: Probability for every endpoint × 30 days, 1 year, 5 years; cumulative risk never falls with a longer horizon | D5: table of % | E5: AI model
A6: AMI | B6: Model performance | C6: Hold-out C-statistic with 95% CI, target, target met (CI lower bound ≥ target), calibration slope | D6: numbers | E6: Bundle manifest
A7: AMI | B7: Risk drivers | C7: Top 8 factors: change in risk when each factor is set to the training cohort's typical value (percentage points) | D7: list | E7: AI model
A8: AMI | B8: Published equations | C8: Pooled Cohort Equations (2013 ACC/AHA) | D8: % / score | E8: Published equations
A9: AMI | B9: Clinical considerations | C9: Guideline-anchored notes (statin, BP, GDMT, anticoagulation, ICD screen) from published equations and measured values, never from the AI risk | D9: text | E9: App rules
A10: AMI | B10: Provenance | C10: Model bundle id, training data source, number of patients, label governance (adjudicated cases, κ range, release id) | D10: text | E10: Bundle manifest
A11: Stroke | B11: Primary risk | C11: 5-year probability of any stroke or tia (falls back to 1-year / 30-day if no 5-year model) | D11: 0–100 % | E11: AI model (calibrated gradient boosting)
A12: Stroke | B12: Risk category | C12: Low <5%, Moderate 5–10%, High 10–20%, Very high ≥20% of the 5-year risk (display bands, not treatment thresholds) | D12: category | E12: App rule
A13: Stroke | B13: Risk by horizon | C13: Probability for every endpoint × 30 days, 1 year, 5 years; cumulative risk never falls with a longer horizon | D13: table of % | E13: AI model
... A43: AF | B43: Not applicable | C43: Patient already has atrial fibrillation. The new-onset AF model does not apply; recurrence prediction needs rhythm-monitoring data that this form does not collect. | D43: text | E43: App rule

Sheet Auto-labelling
A1: Score = bias + Σ weights of votes → probability. ≥80% auto-confirmed, ≤20% auto-rejected, otherwise uncertain (sent to cardiologists). Expert-set starting weights (label model expert-v1); refit from adjudication with refit-label-model.
A2: Outcome family | B2: Labelling function | C2: Evidence it checks | D2: Weight when it supports (+) | E2: Weight when it opposes (−) | F2: Notes
A3: ami | B3: (bias) | C3: Starting log-odds before any evidence | D3: -1
A4: ami | B4: acute_visit | C4: Code recorded in an inpatient/ED visit (+) vs outpatient only (−) | D4: 1 | E4: 1.5
A5: ami | B5: primary_dx | C5: Coded as primary/principal diagnosis | D5: 0.8 | E5: 0
A6: ami | B6: no_dx_code | C6: Evidence-only candidate (no outcome diagnosis code) | D6: 0 | E6: 0.5
A7: ami | B7: trop_rise_fall | C7: Troponin >99th-pct URL with rise/fall ≥20% | D7: 2.5 | E7: 0
A8: ami | B8: trop_elevated_flat | C8: Troponin elevated without documented rise/fall | D8: 0.5 | E8: 0
A9: ami | B9: trop_normal | C9: Troponin measured and all values ≤ URL | D9: 0 | E9: 3
A10: ami | B10: coronary_procedure | C10: Coronary angiography or PCI in window | D10: 1 | E10: 0
A11: ami | B11: note_mi | C11: MI affirmed (+) / negated (−) in notes | D11: 1.5 | E11: 2
A12: ami | B12: note_mi_historical | C12: MI mentioned only as history | D12: 0 | E12: 1.5
A13: stroke | B13: (bias) | C13: Starting log-odds before any evidence | D13: -1
A14: stroke | B14: acute_visit | C14: Code recorded in an inpatient/ED visit (+) vs outpatient only (−) | D14: 1 | E14: 1.5
A15: stroke | B15: primary_dx | C15: Coded as primary/principal diagnosis | D15: 0.8 | E15: 0
A16: stroke | B16: no_dx_code | C16: Evidence-only candidate (no outcome diagnosis code) | D16: 0 | E16: 0.5
A17: stroke | B17: neuroimaging | C17: Head CT/MRI in window (+); acute visit without imaging (−) | D17: 0.8 | E17: 1.5
A18: stroke | B18: img_infarct | C18: Acute infarct / restricted diffusion reported | D18: 2 | E18: 0
A19: stroke | B19: img_hemorrhage | C19: Acute intracranial hemorrhage reported | D19: 2.5 | E19: 0
A20: stroke | B20: img_negative | C20: 'No acute intracranial abnormality' without infarct/hemorrhage | D20: 0 | E20: 0.7
A21: stroke | B21: note_stroke | C21: Stroke/TIA affirmed (+) / negated or history-only (−) | D21: 1.5 | E21: 2
A22: stroke | B22: reperfusion | C22: Thrombolysis or thrombectomy | D22: 1.5 | E22: 0
A23: hf | B23: (bias) | C23: Starting log-odds before any evidence | D23: -1
A24: hf | B24: acute_visit | C24: Code recorded in an inpatient/ED visit (+) vs outpatient only (−) | D24: 1 | E24: 1
A25: hf | B25: primary_dx | C25: Coded as primary/principal diagnosis | D25: 0.8 | E25: 0
A26: hf | B26: no_dx_code | C26: Evidence-only candidate (no outcome diagnosis code) | D26: 0 | E26: 0.5
A27: hf | B27: natriuretic_peptide | C27: BNP/NT-proBNP above rule-in (+) / all below rule-out (−) | D27: 1.5 | E27: 2
A28: hf | B28: note_hf | C28: Acute/decompensated HF affirmed (+) / HF negated (−) | D28: 1.5 | E28: 1.5
A29: hf | B29: echo | C29: Echocardiogram or LVEF reported in window | D29: 0.3 | E29: 0
A30: scd | B30: (bias) | C30: Starting log-odds before any evidence | D30: -1
A31: scd | B31: acute_visit | C31: Code recorded in an inpatient/ED visit (+) vs outpatient only (−) | D31: 1 | E31: 1
A32: scd | B32: primary_dx | C32: Coded as primary/principal diagnosis | D32: 0.8 | E32: 0
A33: scd | B33: no_dx_code | C33: Evidence-only candidate (no outcome diagnosis code) | D33: 0 | E33: 0.5
A34: scd | B34: resuscitation | C34: CPR or defibrillation in window | D34: 2.5 | E34: 0
A35: scd | B35: note_arrest | C35: Arrest/VF/sustained VT/ROSC affirmed (+) / negated (−) | D35: 1.5 | E35: 1.5
A36: scd | B36: note_nsvt | C36: Only non-sustained VT documented | D36: 0 | E36: 2.5
A37: scd | B37: died_within_1d | C37: Death within 1 day | D37: 1 | E37: 0
A38: af | B38: (bias) | C38: Starting log-odds before any evidence | D38: 0
A39: af | B39: no_dx_code | C39: Evidence-only candidate (no outcome diagnosis code) | D39: 0 | E39: 0.5
A40: af | B40: repeat_af_codes | C40: AF coded on ≥2 dates within 1 year (+) / single outpatient code (−) | D40: 1.5 | E40: 0.5
...

Sheet Annotation
A1: Automatic annotation: how candidate episodes, note context, subtypes and imaging values are derived.
A2: Rule | B2: Applies to | C2: Logic | D2: Evidence / file
A3: Episode building | B3: All outcomes | C3: Post-index outcome codes for one patient and family with ≤7 days between consecutive codes form one candidate episode; date = first code | D3: Codes
A4: Evidence-only candidates | B4: AMI, Stroke, SCD, AF | C4: PCI, thrombolysis/thrombectomy, CPR or cardioversion with no outcome code within 7 days creates a candidate (finds missed codes) | D4: Procedures
A5: Label relevance | B5: All outcomes | C5: Candidates after a patient's first auto-confirmed (and definition-eligible) event cannot change a label and are not adjudicated | D5: Auto-labels
A6: Note context (NegEx-style) | B6: All outcomes | C6: Each mention classed as affirmed, negated (no / ruled out / without …), historical (history of / prior / s/p) or hypothetical (rule out / evaluate for / possible) | D6: Notes, 45-character window
A7: Mention patterns | B7: All outcomes | C7: ami: ami, nstemi, stemi, type2_mi; stroke: stroke, stroke_ischemic_img, stroke_hem_img, no_acute_intracranial; hf: hf_acute, hf_any; scd: arrest, nsvt, vf; af: af, flutter | D7: training/nlp.py
A8: Troponin kinetics | B8: AMI | C8: Values normalised to ng/L; URL = range_high, else Mayo TRPS hs-TnT ≤15 (M) / ≤10 (F) ng/L; rise/fall = ≥20% change above URL, or Mayo rule ≥10 ng/L in 2 h / ≥12 ng/L in 6 h | D8: Labs −1 to +3 d
A9: Natriuretic peptides | B9: HF | C9: Rule-in BNP ≥100 or NT-proBNP ≥450/900/1800 pg/mL (age <50 / 50–75 / >75); rule-out BNP <100 and NT-proBNP <300 | D9: Labs −2 to +3 d
A10: AMI subtype | B10: AMI | C10: Code subtype hints (Candidate codes tab): I21.A1 → type 2; I21.0–I21.3, I22.0/.1/.8/.9, ICD-9 410.0x–410.6x and 410.8x → STEMI; I21.4, I22.2, ICD-9 410.7x → NSTEMI; else unspecified. A 'type 2 MI / demand ischemia' or STEMI/NSTEMI mention in notes also sets it. | D10: Codes + notes
A11: Stroke subtype | B11: Stroke | C11: Haemorrhage on imaging or I60–I62 → haemorrhagic; acute infarct or I63 → ischaemic; G45 → TIA; else unknown | D11: Codes + reports
A12: HF subtype | B12: HF | C12: LVEF from echo/imaging −7 to +30 d: ≤40% HFrEF, 41–49% HFmrEF, ≥50% HFpEF; else I50.2/I50.4 → HFrEF, I50.3 → HFpEF; else unknown | D12: Echo notes + codes
A13: SCD subtype | B13: SCD | C13: VF mention or I49.01 → VF; I47.2 with arrest → sustained VT; I46 or arrest → arrest; else unknown | D13: Codes + notes
... A17: Annotation verification | B17: LVEF, CAC | C17: 100 reports (80% with an extracted value, 20% without) checked by a cardiologist; accuracy weighted by 1/sampling probability; gate ≥90% | D17: Workbench

Sheet Automatic audit
A1: 22 checks run on every label run (training/audit.py); thresholds from data/governance.json. Warnings must be acknowledged and failures waived with a written reason or fixed before adjudication.
A2: Check id | B2: Category | C2: What is checked | D2: Warn when | E2: Fail when
A3: schema | B3: Schema | C3: Required columns present in the features table | D3: — | E3: any missing
A4: orphans | B4: Schema | C4: Candidates for patients not in the cohort | D4: — | E4: > 0
A5: evidence_tables | B5: Schema | C5: Labs, procedures and notes tables are non-empty | D5: — | E5: any empty
A6: cohort_size | B6: Cohort | C6: Number of patients | D6: — | E6: < 1,000
A7: duplicates | B7: Cohort | C7: Duplicate patients | D7: — | E7: > 0
A8: age_range | B8: Cohort | C8: Age at index outside 18–89 | D8: — | E8: > 0
A9: followup_negative | B9: Temporal | C9: Negative follow-up time | D9: — | E9: > 0
A10: followup_5y | B10: Temporal | C10: Share with ≥5 years follow-up or death | D10: < 30% | E10: —
A11: events_after_death | B11: Temporal | C11: Candidate events more than 1 day after recorded death | D11: > 0 | E11: > 0.5% of candidates
A12: events_after_index | B12: Leakage | C12: Candidate events on or before the index date | D12: — | E12: > 0
A13: plausibility | B13: Data quality | C13: Share of values outside each input's clinical range (worst feature); cleared to missing in the release | D13: > 0.1% | E13: > 1%
... A24: annotation_yield | B24: Annotation | C24: Reports mentioning LVEF/CAC where a value was extracted | D24: < 90% | E24: —

Sheet Release gates
A1: Training on Mayo Clinic Platform data requires a release in which every gate passed or was waived.
A2: Gate | B2: Requirement | C2: Scope | D2: Who may waive
A3: Automatic audit resolved | B3: All warnings acknowledged, all failures waived (written reason) or fixed | C3: All | D3: Data scientist
A4: Dataset approved | B4: Data scientist approval; creates the adjudication sample | C4: All | D4: —
A5: All cases final | B5: No open reads or unresolved disagreements | C5: All | D5: —
A6: Inter-reader agreement | B6: Cohen's κ ≥ 0.6 on ≥10 double reads | C6: Per outcome | D6: Lead cardiologist
A7: PPV of auto-confirmed labels | B7: ≥ 85% on 50 random cases | C7: Per outcome | D7: Lead cardiologist
A8: NPV of auto-rejected labels | B8: ≥ 85% on 50 random cases | C8: Per outcome | D8: Lead cardiologist
A9: Indeterminate cases | B9: ≤ 15% of final cases | C9: Per outcome | D9: Lead cardiologist
A10: LVEF / CAC extraction accuracy | B10: ≥ 90% (weighted) | C10: Per field | D10: Data scientist
A11: Audit trail intact | B11: Hash chain verifies end to end | C11: All | D11: Cannot be waived
A12: Release sign-offs | B12: Data scientist + lead cardiologist, two different people | C12: All | D12: Cannot be waived

Sheet Demo validation
A1: SYNTHETIC DATA WITH SIMULATED ADJUDICATION: pipeline test only, not evidence of clinical performance. Real figures come from VALIDATION_REPORT.md after training on the Mayo Clinic Platform release. 'Meets target' = CI lower bound ≥ target.
A2: Calculator | B2: Endpoint | C2: Horizon | D2: Hold-out C-statistic | E2: 95% CI low | F2: 95% CI high | G2: Target | H2: Meets target | I2: Calibration slope | J2: Expected / observed | K2: Test patients | L2: Test events / note
A3: AMI | B3: ami | C3: 30d | D3: 0.737 | E3: 0.643 | F3: 0.839 | G3: 0.82 | H3: =IF(D3="","not trained",IF(E3>=G3,"Yes","No")) | I3: 0.98 | J3: 1 | K3: 12000 | L3: 26
A4: AMI | B4: ami | C4: 1y | D4: 0.82 | E4: 0.789 | F4: 0.847 | G4: 0.82 | H4: =IF(D4="","not trained",IF(E4>=G4,"Yes","No")) | I4: 0.97 | J4: 1.04 | K4: 11351 | L4: 254
A5: AMI | B5: ami | C5: 5y | D5: 0.812 | E5: 0.794 | F5: 0.828 | G5: 0.82 | H5: =IF(D5="","not trained",IF(E5>=G5,"Yes","No")) | I5: 1.04 | J5: 1.06 | K5: 6928 | L5: 800
A6: Stroke | B6: any_stroke | C6: 1y | D6: 0.751 | E6: 0.71 | F6: 0.796 | G6: 0.75 | H6: =IF(D6="","not trained",IF(E6>=G6,"Yes","No")) | I6: 0.89 | J6: 1.03 | K6: 11342 | L6: 144
A7: Stroke | B7: any_stroke | C7: 5y | D7: 0.747 | E7: 0.727 | F7: 0.767 | G7: 0.75 | H7: =IF(D7="","not trained",IF(E7>=G7,"Yes","No")) | I7: 0.88 | J7: 1.01 | K7: 6815 | L7: 531
A8: Stroke | B8: ischemic_stroke | C8: 1y | D8: 0.735 | E8: 0.697 | F8: 0.777 | G8: 0.75 | H8: =IF(D8="","not trained",IF(E8>=G8,"Yes","No")) | I8: 0.79 | J8: 1.02 | K8: 11341 | L8: 111
A9: Stroke | B9: ischemic_stroke | C9: 5y | D9: 0.74 | E9: 0.72 | F9: 0.768 | G9: 0.75 | H9: =IF(D9="","not trained",IF(E9>=G9,"Yes","No")) | I9: 0.86 | J9: 0.98 | K9: 6775 | L9: 405
A10: Stroke | B10: hemorrhagic_stroke | C10: 5y | D10: 0.696 | E10: 0.593 | F10: 0.779 | G10: 0.75 | H10: =IF(D10="","not trained",IF(E10>=G10,"Yes","No")) | I10: 0.99 | J10: 1.09 | K10: 6650 | L10: 28
A11: Stroke | B11: tia | C11: 1y | D11: 0.735 | E11: 0.629 | F11: 0.858 | G11: 0.75 | H11: =IF(D11="","not trained",IF(E11>=G11,"Yes","No")) | I11: 1 | J11: 1.16 | K11: 11337 | L11: 24
A12: Stroke | B12: tia | C12: 5y | D12: 0.689 | E12: 0.637 | F12: 0.729 | G12: 0.75 | H12: =IF(D12="","not trained",IF(E12>=G12,"Yes","No")) | I12: 1.27 | J12: 1.1 | K12: 6676 | L12: 98
A13: Heart failure | B13: hf | C13: 30d | D13: 0.919 | E13: 0.878 | F13: 0.954 | G13: 0.8 | H13: =IF(D13="","not trained",IF(E13>=G13,"Yes","No")) | I13: 1.18 | J13: 0.8 | K13: 12000 | L13: 34
A14: Heart failure | B14: hf | C14: 1y | D14: 0.876 | E14: 0.857 | F14: 0.894 | G14: 0.8 | H14: =IF(D14="","not trained",IF(E14>=G14,"Yes","No")) | I14: 1.02 | J14: 0.96 | K14: 11347 | L14: 313
... A25: AF | B25: af | C25: 5y | D25: 0.801 | E25: 0.79 | F25: 0.817 | G25: 0.8 | H25: =IF(D25="","not trained",IF(E25>=G25,"Yes","No")) | I25: 1.02 | J25: 0.98 | K25: 6677 | L25: 959
A26: Stroke | B26: any_stroke | C26: 30d | G26: 0.75 | H26: =IF(D26="","not trained",IF(E26>=G26,"Yes","No")) | L26: insufficient events (train 52, test <11)
A27: Stroke | B27: ischemic_stroke | C27: 30d | G27: 0.75 | H27: =IF(D27="","not trained",IF(E27>=G27,"Yes","No")) | L27: insufficient events (train 41, test <11)
A28: Stroke | B28: hemorrhagic_stroke | C28: 30d | G28: 0.75 | H28: =IF(D28="","not trained",IF(E28>=G28,"Yes","No")) | L28: insufficient events (train <11, test <11)
A29: Stroke | B29: hemorrhagic_stroke | C29: 1y | G29: 0.75 | H29: =IF(D29="","not trained",IF(E29>=G29,"Yes","No")) | L29: insufficient events (train 28, test <11)
A30: Stroke | B30: tia | C30: 30d | G30: 0.75 | H30: =IF(D30="","not trained",IF(E30>=G30,"Yes","No")) | L30: insufficient events (train <11, test <11)
A31: Heart failure | B31: hfpef | C31: 30d | G31: 0.8 | H31: =IF(D31="","not trained",IF(E31>=G31,"Yes","No")) | L31: insufficient events (train 27, test <11)
A32: SCD | B32: scd | C32: 30d | G32: 0.78 | H32: =IF(D32="","not trained",IF(E32>=G32,"Yes","No")) | L32: insufficient events (train 14, test <11)
